Workbook

Sheet 1-COSTO X KM
A1: ANEXO 1 - DETERMINACIÓN DEL COSTO POR KM
L2: PORCENTAJE DE INCIDENCIA DE CADA RUBRO EN EL COSTO/KM | V2: VARIACION PORCENTUAL POR RUBRO COSTO/KM. OCTUBRE 2025/ OCTUBRE2024 | AF2: VARIACION PORCENTUAL POR RUBRO COSTO/KM. OCTUBRE 2025/ JUNIO 2025
A3: RUBROS | B3: DF $/km | C3: SGI $/km | D3: SGI KM $/km | E3: SGII $/km | F3: INP $/km | G3: UPA $/km | H3: UPA KM $/km | I3: UMA 1 $/km | J3: UMA 2 $/km | L3: =+A3 -> RUBROS | M3: DF $/km | N3: SGI $/km | O3: SGI KM $/km | P3: SGII $/km | Q3: INP $/km | R3: UPA $/km | S3: UPA KM $/km | T3: UMA 1 $/km | U3: UMA 2 $/km | V3: =+A3 -> RUBROS | W3: DF $/km | X3: SGI $/km | Y3: SGI KM $/km | Z3: SGII $/km | AA3: INP $/km | AB3: UPA $/km | AC3: UPA KM $/km | AD3: UMA 1 $/km | AE3: UMA 2 $/km | AF3: =+L3 -> RUBROS | AG3: DF $/km | AH3: SGI $/km | AI3: SGI KM $/km | AJ3: SGII $/km | AK3: INP $/km | AL3: UPA $/km | AM3: UPA KM $/km | AN3: UMA 1 $/km | AO3: UMA 2 $/km
A4: 1. COMBUSTIBLE | B4: =+'3- REND Y CONS'!B4*'5-PRECIOS SIN IVA'!B5 -> 769.86709 | C4: =+'3- REND Y CONS'!C4*'5-PRECIOS SIN IVA'!C5 -> 626.32826 | D4: =+'3- REND Y CONS'!D4*'5-PRECIOS SIN IVA'!D5 -> 588.76106 | E4: =+'3- REND Y CONS'!E4*'5-PRECIOS SIN IVA'!E5 -> 462.23252 | F4: =+'3- REND Y CONS'!F4*'5-PRECIOS SIN IVA'!F5 -> 407.45207 | G4: =+'3- REND Y CONS'!G4*'5-PRECIOS SIN IVA'!G5 -> 516.22122 | H4: =+'3- REND Y CONS'!H4*'5-PRECIOS SIN IVA'!H5 -> 527.32088 | I4: =+'3- REND Y CONS'!I4*'5-PRECIOS SIN IVA'!I5 -> 501.95111 | J4: =+'3- REND Y CONS'!J4*'5-PRECIOS SIN IVA'!J5 -> 501.95112 | L4: =+A4 -> 1. COMBUSTIBLE | M4: =+B4/B$51 -> 0.198636 | N4: =+C4/C$51 -> 0.18093229 | O4: =+D4/D$51 -> 0.21115931 | P4: =+E4/E$51 -> 0.19651053 | Q4: =+F4/F$51 -> 0.17140724 | R4: =+G4/G$51 -> 0.16772597 | S4: =+H4/H$51 -> 0.21305062 | T4: =+I4/I$51 -> 0.16147247 | U4: =+J4/J$51 -> 0.17040527 | V4: =+A4 -> 1. COMBUSTIBLE | W4: =+B4/'[1]1-COSTO X KM'!B4-1 -> 0.63747829 | X4: =+C4/'[1]1-COSTO X KM'!C4-1 -> 0.34701109 | Y4: =+D4/'[1]1-COSTO X KM'!D4-1 -> 0.34701109 | Z4: =+E4/'[1]1-COSTO X KM'!E4-1 -> 0.34701109 | AA4: =+F4/'[1]1-COSTO X KM'!F4-1 -> 0.34701109 | AB4: =+G4/'[1]1-COSTO X KM'!G4-1 -> 0.34701109 | AC4: =+H4/'[1]1-COSTO X KM'!H4-1 -> 0.34701109 | AD4: =+I4/'[1]1-COSTO X KM'!I4-1 -> 0.34701109 | AE4: =+J4/'[1]1-COSTO X KM'!J4-1 -> 0.34701106 | AF4: =+L4 -> 1. COMBUSTIBLE | AG4: =+B4/'[2]1-COSTO X KM'!B4-1 -> 0.47278978 | AH4: =+C4/'[2]1-COSTO X KM'!C4-1 -> 0.21153617 | AI4: =+D4/'[2]1-COSTO X KM'!D4-1 -> 0.21153617 | AJ4: =+E4/'[2]1-COSTO X KM'!E4-1 -> 0.21153617 | AK4: =+F4/'[2]1-COSTO X KM'!F4-1 -> 0.21153617 | AL4: =+G4/'[2]1-COSTO X KM'!G4-1 -> 0.21153617 | AM4: =+H4/'[2]1-COSTO X KM'!H4-1 -> 0.21153617 | AN4: =+I4/'[2]1-COSTO X KM'!I4-1 -> 0.21153617 | AO4: =+J4/'[2]1-COSTO X KM'!J4-1 -> 0.21153614
A5: 2. LUBRICANTES | B5: =+('3- REND Y CONS'!B5*'5-PRECIOS SIN IVA'!B6+('3- REND Y CONS'!B6+'3- REND Y CONS'!B7)*'5-PRECIOS SIN IVA'!B7)*(1+'2- EMP. REP'!B9) -> 21.787509 | C5: =+('3- REND Y CONS'!C5*'5-PRECIOS SIN IVA'!C6+('3- REND Y CONS'!C6+'3- REND Y CONS'!C7)*'5-PRECIOS SIN IVA'!C7)*(1+'2- EMP. REP'!C9) -> 21.787509 | D5: =+('3- REND Y CONS'!D5*'5-PRECIOS SIN IVA'!D6+('3- REND Y CONS'!D6+'3- REND Y CONS'!D7)*'5-PRECIOS SIN IVA'!D7)*(1+'2- EMP. REP'!D9) -> 21.787509 | E5: =+('3- REND Y CONS'!E5*'5-PRECIOS SIN IVA'!E6+('3- REND Y CONS'!E6+'3- REND Y CONS'!E7)*'5-PRECIOS SIN IVA'!E7)*(1+'2- EMP. REP'!E9) -> 21.787509 | F5: =+('3- REND Y CONS'!F5*'5-PRECIOS SIN IVA'!F6+('3- REND Y CONS'!F6+'3- REND Y CONS'!F7)*'5-PRECIOS SIN IVA'!F7)*(1+'2- EMP. REP'!F9) -> 21.787509 | G5: =+('3- REND Y CONS'!G5*'5-PRECIOS SIN IVA'!G6+('3- REND Y CONS'!G6+'3- REND Y CONS'!G7)*'5-PRECIOS SIN IVA'!G7)*(1+'2- EMP. REP'!G9) -> 21.787509 | H5: =+('3- REND Y CONS'!H5*'5-PRECIOS SIN IVA'!H6+('3- REND Y CONS'!H6+'3- REND Y CONS'!H7)*'5-PRECIOS SIN IVA'!H7)*(1+'2- EMP. REP'!H9) -> 21.787509 | I5: =+('3- REND Y CONS'!I5*'5-PRECIOS SIN IVA'!I6+('3- REND Y CONS'!I6+'3- REND Y CONS'!I7)*'5-PRECIOS SIN IVA'!I7)*(1+'2- EMP. REP'!I9) -> 21.787509 | J5: =+('3- REND Y CONS'!J5*'5-PRECIOS SIN IVA'!J6+('3- REND Y CONS'!J6+'3- REND Y CONS'!J7)*'5-PRECIOS SIN IVA'!J7)*(1+'2- EMP. REP'!J9) -> 21.787509 | L5: =+A5 -> 2. LUBRICANTES | M5: =+B5/B$51 -> 0.0056214686 | N5: =+C5/C$51 -> 0.0062939264 | O5: =+D5/D$51 -> 0.0078140961 | P5: =+E5/E$51 -> 0.0092626002 | Q5: =+F5/F$51 -> 0.0091655859 | R5: =+G5/G$51 -> 0.0070790024 | S5: =+H5/H$51 -> 0.0088026901 | T5: =+I5/I$51 -> 0.0070088162 | U5: =+J5/J$51 -> 0.0073965499 | V5: =+A5 -> 2. LUBRICANTES | W5: =+B5/'[1]1-COSTO X KM'!B5-1 -> 0.2474288 | X5: =+C5/'[1]1-COSTO X KM'!C5-1 -> 0.2474288 | Y5: =+D5/'[1]1-COSTO X KM'!D5-1 -> 0.2474288 | Z5: =+E5/'[1]1-COSTO X KM'!E5-1 -> 0.2474288 | AA5: =+F5/'[1]1-COSTO X KM'!F5-1 -> 0.2474288 | AB5: =+G5/'[1]1-COSTO X KM'!G5-1 -> 0.2474288 | AC5: =+H5/'[1]1-COSTO X KM'!H5-1 -> 0.2474288 | AD5: =+I5/'[1]1-COSTO X KM'!I5-1 -> 0.2474288 | AE5: =+J5/'[1]1-COSTO X KM'!J5-1 -> 0.2474288 | AF5: =+L5 -> 2. LUBRICANTES | AG5: =+B5/'[2]1-COSTO X KM'!B5-1 -> 0.20023066 | AH5: =+C5/'[2]1-COSTO X KM'!C5-1 -> 0.20023066 | AI5: =+D5/'[2]1-COSTO X KM'!D5-1 -> 0.20023066 | AJ5: =+E5/'[2]1-COSTO X KM'!E5-1 -> 0.20023066 | AK5: =+F5/'[2]1-COSTO X KM'!F5-1 -> 0.20023066 | AL5: =+G5/'[2]1-COSTO X KM'!G5-1 -> 0.20023066 | AM5: =+H5/'[2]1-COSTO X KM'!H5-1 -> 0.20023066 | AN5: =+I5/'[2]1-COSTO X KM'!I5-1 -> 0.20023066 | AO5: =+J5/'[2]1-COSTO X KM'!J5-1 -> 0.20023066
A6: 3. NEUMATICOS | B6: =((+'3- REND Y CONS'!B8*'5-PRECIOS SIN IVA'!B8)+('3- REND Y CONS'!B14*'5-PRECIOS SIN IVA'!B9*'3- REND Y CONS'!B8))*(1+'2- EMP. REP'!B9)/('3- REND Y CONS'!B13) -> 79.139001 | C6: =((+'3- REND Y CONS'!C8*'5-PRECIOS SIN IVA'!C8)+('3- REND Y CONS'!C14*'5-PRECIOS SIN IVA'!C9*'3- REND Y CONS'!C8))*(1+'2- EMP. REP'!C9)/('3- REND Y CONS'!C13) -> 79.139001 | D6: =+C6 -> 79.139001 | E6: =+D6 -> 79.139001 | F6: =+E6 -> 79.139001 | G6: =+F6 -> 79.139001 | H6: =+G6 -> 79.139001 | I6: =+H6 -> 79.139001 | J6: =+I6 -> 79.139001 | L6: =+A6 -> 3. NEUMATICOS | M6: =+B6/B$51 -> 0.02041892 | N6: =+C6/C$51 -> 0.022861496 | O6: =+D6/D$51 -> 0.028383224 | P6: =+E6/E$51 -> 0.033644641 | Q6: =+F6/F$51 -> 0.033292255 | R6: =+G6/G$51 -> 0.025713136 | S6: =+H6/H$51 -> 0.031974105 | T6: =+I6/I$51 -> 0.025458197 | U6: =+J6/J$51 -> 0.026866567 | V6: =+A6 -> 3. NEUMATICOS | W6: =+B6/'[1]1-COSTO X KM'!B6-1 -> 0.24742929 | X6: =+C6/'[1]1-COSTO X KM'!C6-1 -> 0.24742929 | Y6: =+D6/'[1]1-COSTO X KM'!D6-1 -> 0.24742929 | Z6: =+E6/'[1]1-COSTO X KM'!E6-1 -> 0.24742929 | AA6: =+F6/'[1]1-COSTO X KM'!F6-1 -> 0.24742929 | AB6: =+G6/'[1]1-COSTO X KM'!G6-1 -> 0.24742929 | AC6: =+H6/'[1]1-COSTO X KM'!H6-1 -> 0.24742929 | AD6: =+I6/'[1]1-COSTO X KM'!I6-1 -> 0.24742929 | AE6: =+J6/'[1]1-COSTO X KM'!J6-1 -> 0.24742929 | AF6: =+L6 -> 3. NEUMATICOS | AG6: =+B6/'[2]1-COSTO X KM'!B6-1 -> 0.20023086 | AH6: =+C6/'[2]1-COSTO X KM'!C6-1 -> 0.20023086 | AI6: =+D6/'[2]1-COSTO X KM'!D6-1 -> 0.20023086 | AJ6: =+E6/'[2]1-COSTO X KM'!E6-1 -> 0.20023086 | AK6: =+F6/'[2]1-COSTO X KM'!F6-1 -> 0.20023086 | AL6: =+G6/'[2]1-COSTO X KM'!G6-1 -> 0.20023086 | AM6: =+H6/'[2]1-COSTO X KM'!H6-1 -> 0.20023086 | AN6: =+I6/'[2]1-COSTO X KM'!I6-1 -> 0.20023086 | AO6: =+J6/'[2]1-COSTO X KM'!J6-1 -> 0.20023086
A7: 4. ENGRASE Y LAVADO | B7: =+('3- REND Y CONS'!B16*'5-PRECIOS SIN IVA'!B10+'3- REND Y CONS'!B17*'5-PRECIOS SIN IVA'!B11+'3- REND Y CONS'!B18*'5-PRECIOS SIN IVA'!B12+'3- REND Y CONS'!B19*'5-PRECIOS SIN IVA'!B13+'3- REND Y CONS'!B20*'5-PRECIOS SIN IVA'!B14+'3- REND Y CONS'!B21*'5-PRECIOS SIN IVA'!B15+'3- REND Y CONS'!B22*'5-PRECIOS SIN IVA'!B16)/'3- REND Y CONS'!B23 -> 54.825193 | C7: =+('3- REND Y CONS'!C16*'5-PRECIOS SIN IVA'!C10+'3- REND Y CONS'!C17*'5-PRECIOS SIN IVA'!C11+'3- REND Y CONS'!C18*'5-PRECIOS SIN IVA'!C12+'3- REND Y CONS'!C19*'5-PRECIOS SIN IVA'!C13+'3- REND Y CONS'!C20*'5-PRECIOS SIN IVA'!C14+'3- REND Y CONS'!C21*'5-PRECIOS SIN IVA'!C15+'3- REND Y CONS'!C22*'5-PRECIOS SIN IVA'!C16)/'3- REND Y CONS'!C23 -> 54.825193 | D7: =+C7 -> 54.825193 | E7: =+D7 -> 54.825193 | F7: =+E7 -> 54.825193 | G7: =+F7 -> 54.825193 | H7: =+G7 -> 54.825193 | I7: =+H7 -> 54.825193 | J7: =+I7 -> 54.825193 | L7: =+A7 -> 4. ENGRASE Y LAVADO | M7: =+B7/B$51 -> 0.014145633 | N7: =+C7/C$51 -> 0.015837778 | O7: =+D7/D$51 -> 0.01966307 | P7: =+E7/E$51 -> 0.023308027 | Q7: =+F7/F$51 -> 0.023063904 | R7: =+G7/G$51 -> 0.017813311 | S7: =+H7/H$51 -> 0.022150728 | T7: =+I7/I$51 -> 0.017636697 | U7: =+J7/J$51 -> 0.018612374 | V7: =+A7 -> 4. ENGRASE Y LAVADO | W7: =+B7/'[1]1-COSTO X KM'!B7-1 -> 0.2474293 | X7: =+C7/'[1]1-COSTO X KM'!C7-1 -> 0.2474293 | Y7: =+D7/'[1]1-COSTO X KM'!D7-1 -> 0.2474293 | Z7: =+E7/'[1]1-COSTO X KM'!E7-1 -> 0.2474293 | AA7: =+F7/'[1]1-COSTO X KM'!F7-1 -> 0.2474293 | AB7: =+G7/'[1]1-COSTO X KM'!G7-1 -> 0.2474293 | AC7: =+H7/'[1]1-COSTO X KM'!H7-1 -> 0.2474293 | AD7: =+I7/'[1]1-COSTO X KM'!I7-1 -> 0.2474293 | AE7: =+J7/'[1]1-COSTO X KM'!J7-1 -> 0.2474293 | AF7: =+L7 -> 4. ENGRASE Y LAVADO | AG7: =+B7/'[2]1-COSTO X KM'!B7-1 -> 0.2002308 | AH7: =+C7/'[2]1-COSTO X KM'!C7-1 -> 0.2002308 | AI7: =+D7/'[2]1-COSTO X KM'!D7-1 -> 0.2002308 | AJ7: =+E7/'[2]1-COSTO X KM'!E7-1 -> 0.2002308 | AK7: =+F7/'[2]1-COSTO X KM'!F7-1 -> 0.2002308 | AL7: =+G7/'[2]1-COSTO X KM'!G7-1 -> 0.2002308 | AM7: =+H7/'[2]1-COSTO X KM'!H7-1 -> 0.2002308 | AN7: =+I7/'[2]1-COSTO X KM'!I7-1 -> 0.2002308 | AO7: =+J7/'[2]1-COSTO X KM'!J7-1 -> 0.2002308
A8: 5. REPARACION Y MANTENIMIENTO DEL MATERIAL RODANTE | B8: =+B9+B10 -> 256.95858 | C8: =+C9+C10 -> 236.57637 | D8: =+D9+D10 -> 179.31954 | E8: =+E9+E10 -> 331.63573 | F8: =+F9+F10 -> 157.16111 | G8: =+G9+G10 -> 211.81001 | H8: =+H9+H10 -> 155.52701 | I8: =+I9+I10 -> 197.02863 | J8: =+J9+J10 -> 183.0581 | L8: =+A8 -> 5. REPARACION Y MANTENIMIENTO DEL MATERIAL RODANTE | M8: =+B8/B$51 -> 0.066298747 | N8: =+C8/C$51 -> 0.068341645 | O8: =+D8/D$51 -> 0.064313003 | P8: =+E8/E$51 -> 0.14098946 | Q8: =+F8/F$51 -> 0.066114655 | R8: =+G8/G$51 -> 0.068819412 | S8: =+H8/H$51 -> 0.062836743 | T8: =+I8/I$51 -> 0.063382069 | U8: =+J8/J$51 -> 0.062145623 | V8: =+A8 -> 5. REPARACION Y MANTENIMIENTO DEL MATERIAL RODANTE | W8: =+B8/'[1]1-COSTO X KM'!B8-1 -> 0.50542842 | X8: =+C8/'[1]1-COSTO X KM'!C8-1 -> 0.77630776 | Y8: =+D8/'[1]1-COSTO X KM'!D8-1 -> 0.79036721 | Z8: =+E8/'[1]1-COSTO X KM'!E8-1 -> 0.66283191 | AA8: =+F8/'[1]1-COSTO X KM'!F8-1 -> 0.9259468 | AB8: =+G8/'[1]1-COSTO X KM'!G8-1 -> 0.5626251 | AC8: =+H8/'[1]1-COSTO X KM'!H8-1 -> 0.72614549 | AD8: =+I8/'[1]1-COSTO X KM'!I8-1 -> 0.59033901 | AE8: =+J8/'[1]1-COSTO X KM'!J8-1 -> 0.63489944 | AF8: =+L8 -> 5. REPARACION Y MANTENIMIENTO DEL MATERIAL RODANTE | AG8: =+B8/'[2]1-COSTO X KM'!B8-1 -> 0.33283839 | AH8: =+C8/'[2]1-COSTO X KM'!C8-1 -> 0.38543489 | AI8: =+D8/'[2]1-COSTO X KM'!D8-1 -> 0.400205 | AJ8: =+E8/'[2]1-COSTO X KM'!E8-1 -> 0.31315699 | AK8: =+F8/'[2]1-COSTO X KM'!F8-1 -> 0.53123515 | AL8: =+G8/'[2]1-COSTO X KM'!G8-1 -> 0.3955749 | AM8: =+H8/'[2]1-COSTO X KM'!H8-1 -> 0.48715587 | AN8: =+I8/'[2]1-COSTO X KM'!I8-1 -> 0.41863609 | AO8: =+J8/'[2]1-COSTO X KM'!J8-1 -> 0.46531434
A9: . Reparación y mant. chasis (incluye boletera y rampa) | B9: =+'3- REND Y CONS'!B24*('5-PRECIOS SIN IVA'!B17-6*'5-PRECIOS SIN IVA'!B8)*'2- EMP. REP'!B11/'2- EMP. REP'!B10 -> 176.60975 | C9: =+'3- REND Y CONS'!C24*('5-PRECIOS SIN IVA'!C17-6*'5-PRECIOS SIN IVA'!C8)*'2- EMP. REP'!C11/'2- EMP. REP'!C10 -> 162.60089 | D9: =+'3- REND Y CONS'!D24*('5-PRECIOS SIN IVA'!D17-6*'5-PRECIOS SIN IVA'!D8)*'2- EMP. REP'!D11/'2- EMP. REP'!D10 -> 123.2478 | E9: =+'3- REND Y CONS'!E24*('5-PRECIOS SIN IVA'!E17-6*'5-PRECIOS SIN IVA'!E8)*'2- EMP. REP'!E11/'2- EMP. REP'!E10 -> 211.8743 | F9: =+'3- REND Y CONS'!F24*('5-PRECIOS SIN IVA'!F17-6*'5-PRECIOS SIN IVA'!F8)*'2- EMP. REP'!F11/'2- EMP. REP'!F10 -> 108.01813 | G9: =+'3- REND Y CONS'!G24*('5-PRECIOS SIN IVA'!G17-6*'5-PRECIOS SIN IVA'!G8)*'2- EMP. REP'!G11/'2- EMP. REP'!G10 -> 145.57877 | H9: =+'3- REND Y CONS'!H24*('5-PRECIOS SIN IVA'!H17-6*'5-PRECIOS SIN IVA'!H8)*'2- EMP. REP'!H11/'2- EMP. REP'!H10 -> 106.895 | I9: =+'3- REND Y CONS'!I24*('5-PRECIOS SIN IVA'!I17-6*'5-PRECIOS SIN IVA'!I8)*'2- EMP. REP'!I11/'2- EMP. REP'!I10 -> 135.13232 | J9: =+'3- REND Y CONS'!J24*('5-PRECIOS SIN IVA'!J17-6*'5-PRECIOS SIN IVA'!J8)*'2- EMP. REP'!J11/'2- EMP. REP'!J10 -> 125.55062 | L9: =+A9 -> . Reparación y mant. chasis (incluye boletera y rampa) | V9: =+A9 -> . Reparación y mant. chasis (incluye boletera y rampa) | AF9: =+L9 -> . Reparación y mant. chasis (incluye boletera y rampa)
A10: . Reparación y Mant. carrocería | B10: =+'3- REND Y CONS'!B25*'5-PRECIOS SIN IVA'!B18*'2- EMP. REP'!B11/'2- EMP. REP'!B10 -> 80.348824 | C10: =+'3- REND Y CONS'!C25*'5-PRECIOS SIN IVA'!C18*'2- EMP. REP'!C11/'2- EMP. REP'!C10 -> 73.975475 | D10: =+'3- REND Y CONS'!D25*'5-PRECIOS SIN IVA'!D18*'2- EMP. REP'!D11/'2- EMP. REP'!D10 -> 56.07174 | E10: =+'3- REND Y CONS'!E25*'5-PRECIOS SIN IVA'!E18*'2- EMP. REP'!E11/'2- EMP. REP'!E10 -> 119.76143 | F10: =+'3- REND Y CONS'!F25*'5-PRECIOS SIN IVA'!F18*'2- EMP. REP'!F11/'2- EMP. REP'!F10 -> 49.142981 | G10: =+'3- REND Y CONS'!G25*'5-PRECIOS SIN IVA'!G18*'2- EMP. REP'!G11/'2- EMP. REP'!G10 -> 66.231241 | H10: =+'3- REND Y CONS'!H25*'5-PRECIOS SIN IVA'!H18*'2- EMP. REP'!H11/'2- EMP. REP'!H10 -> 48.632013 | I10: =+'3- REND Y CONS'!I25*'5-PRECIOS SIN IVA'!I18*'2- EMP. REP'!I11/'2- EMP. REP'!I10 -> 61.896305 | J10: =+'3- REND Y CONS'!J25*'5-PRECIOS SIN IVA'!J18*'2- EMP. REP'!J11/'2- EMP. REP'!J10 -> 57.50748 | L10: =+A10 -> . Reparación y Mant. carrocería | V10: =+A10 -> . Reparación y Mant. carrocería | AF10: =+L10 -> . Reparación y Mant. carrocería
A11: 6. DEPRECIACION DEL MATERIAL RODANTE | B11: =+B12+B13 -> 309.33279 | C11: =+C12+C13 -> 219.074 | D11: =+D12+D13 -> 166.05315 | E11: =+E12+E13 -> 153.40363 | F11: =+F12+F13 -> 145.53404 | G11: =+G12+G13 -> 196.13991 | H11: =+H12+H13 -> 144.02084 | I11: =+I12+I13 -> 182.44684 | J11: =+J12+J13 -> 169.51024 | L11: =+A11 -> 6. DEPRECIACION DEL MATERIAL RODANTE | M11: =+B11/B$51 -> 0.079811995 | N11: =+C11/C$51 -> 0.063285603 | O11: =+D11/D$51 -> 0.059555007 | P11: =+E11/E$51 -> 0.065217024 | Q11: =+F11/F$51 -> 0.06122337 | R11: =+G11/G$51 -> 0.063728023 | S11: =+H11/H$51 -> 0.058187963 | T11: =+I11/I$51 -> 0.058691258 | U11: =+J11/J$51 -> 0.057546319 | V11: =+A11 -> 6. DEPRECIACION DEL MATERIAL RODANTE | W11: =+B11/'[1]1-COSTO X KM'!B11-1 -> 0.95715192 | X11: =+C11/'[1]1-COSTO X KM'!C11-1 -> 0.77639397 | Y11: =+D11/'[1]1-COSTO X KM'!D11-1 -> 0.7904541 | Z11: =+E11/'[1]1-COSTO X KM'!E11-1 -> 0.66289825 | AA11: =+F11/'[1]1-COSTO X KM'!F11-1 -> 0.92604027 | AB11: =+G11/'[1]1-COSTO X KM'!G11-1 -> 0.56270093 | AC11: =+H11/'[1]1-COSTO X KM'!H11-1 -> 0.72622926 | AD11: =+I11/'[1]1-COSTO X KM'!I11-1 -> 0.59042916 | AE11: =+J11/'[1]1-COSTO X KM'!J11-1 -> 0.63499212 | AF11: =+L11 -> 6. DEPRECIACION DEL MATERIAL RODANTE | AG11: =+B11/'[2]1-COSTO X KM'!B11-1 -> 0.33287973 | AH11: =+C11/'[2]1-COSTO X KM'!C11-1 -> 0.38547786 | AI11: =+D11/'[2]1-COSTO X KM'!D11-1 -> 0.40024843 | AJ11: =+E11/'[2]1-COSTO X KM'!E11-1 -> 0.31319051 | AK11: =+F11/'[2]1-COSTO X KM'!F11-1 -> 0.53128265 | AL11: =+G11/'[2]1-COSTO X KM'!G11-1 -> 0.39561819 | AM11: =+H11/'[2]1-COSTO X KM'!H11-1 -> 0.487202 | AN11: =+I11/'[2]1-COSTO X KM'!I11-1 -> 0.41868747 | AO11: =+J11/'[2]1-COSTO X KM'!J11-1 -> 0.46536741
A12: . Chasis (incluye boletera y rampa) | B12: =+('5-PRECIOS SIN IVA'!B21+('5-PRECIOS SIN IVA'!B21*'5-PRECIOS SIN IVA'!B19))/'2- EMP. REP'!B10 -> 213.91856 | C12: =+('5-PRECIOS SIN IVA'!C21+('5-PRECIOS SIN IVA'!C21*'5-PRECIOS SIN IVA'!C19))/'2- EMP. REP'!C10 -> 151.50025 | D12: =+('5-PRECIOS SIN IVA'!D21+('5-PRECIOS SIN IVA'!D21*'5-PRECIOS SIN IVA'!D19))/'2- EMP. REP'!D10 -> 114.83377 | E12: =+('5-PRECIOS SIN IVA'!E21+('5-PRECIOS SIN IVA'!E21*'5-PRECIOS SIN IVA'!E19))/'2- EMP. REP'!E10 -> 98.704903 | F12: =+('5-PRECIOS SIN IVA'!F21+('5-PRECIOS SIN IVA'!F21*'5-PRECIOS SIN IVA'!F19))/'2- EMP. REP'!F10 -> 100.64382 | G12: =+('5-PRECIOS SIN IVA'!G21+('5-PRECIOS SIN IVA'!G21*'5-PRECIOS SIN IVA'!G19))/'2- EMP. REP'!G10 -> 135.64022 | H12: =+('5-PRECIOS SIN IVA'!H21+('5-PRECIOS SIN IVA'!H21*'5-PRECIOS SIN IVA'!H19))/'2- EMP. REP'!H10 -> 99.597363 | I12: =+('5-PRECIOS SIN IVA'!I21+('5-PRECIOS SIN IVA'!I21*'5-PRECIOS SIN IVA'!I19))/'2- EMP. REP'!I10 -> 125.90694 | J12: =+('5-PRECIOS SIN IVA'!J21+('5-PRECIOS SIN IVA'!J21*'5-PRECIOS SIN IVA'!J19))/'2- EMP. REP'!J10 -> 116.97937 | L12: =+A12 -> . Chasis (incluye boletera y rampa) | V12: =+A12 -> . Chasis (incluye boletera y rampa) | AF12: =+L12 -> . Chasis (incluye boletera y rampa)
A13: . Carrocería | B13: =+'5-PRECIOS SIN IVA'!B22/'2- EMP. REP'!B10 -> 95.414229 | C13: =+'5-PRECIOS SIN IVA'!C22/'2- EMP. REP'!C10 -> 67.573751 | D13: =+'5-PRECIOS SIN IVA'!D22/'2- EMP. REP'!D10 -> 51.219378 | E13: =+'5-PRECIOS SIN IVA'!E22/'2- EMP. REP'!E10 -> 54.698731 | F13: =+'5-PRECIOS SIN IVA'!F22/'2- EMP. REP'!F10 -> 44.890223 | G13: =+'5-PRECIOS SIN IVA'!G22/'2- EMP. REP'!G10 -> 60.499691 | H13: =+'5-PRECIOS SIN IVA'!H22/'2- EMP. REP'!H10 -> 44.423473 | I13: =+'5-PRECIOS SIN IVA'!I22/'2- EMP. REP'!I10 -> 56.539894 | J13: =+'5-PRECIOS SIN IVA'!J22/'2- EMP. REP'!J10 -> 52.530871 | L13: =+A13 -> . Carrocería | V13: =+A13 -> . Carrocería | AF13: =+L13 -> . Carrocería
A14: 7. SEGURO DEL VEHÍCULO | B14: =SUM(B15:B18) -> 207.38517 | C14: =SUM(C15:C18) -> 190.93517 | D14: =SUM(D15:D18) -> 144.72455 | E14: =SUM(E15:E18) -> 104.32364 | F14: =SUM(F15:F18) -> 126.841 | G14: =SUM(G15:G18) -> 170.94683 | H14: =SUM(H15:H18) -> 125.52216 | I14: =SUM(I15:I18) -> 178.69632 | J14: =SUM(J15:J18) -> 166.02566 | L14: =+A14 -> 7. SEGURO DEL VEHÍCULO | M14: =+B14/B$51 -> 0.053508145 | N14: =+C14/C$51 -> 0.055156919 | O14: =+D14/D$51 -> 0.051905498 | P14: =+E14/E$51 -> 0.044351476 | Q14: =+F14/F$51 -> 0.053359569 | R14: =+G14/G$51 -> 0.055542513 | S14: =+H14/H$51 -> 0.050714043 | T14: =+I14/I$51 -> 0.057484756 | U14: =+J14/J$51 -> 0.056363353 | V14: =+A14 -> 7. SEGURO DEL VEHÍCULO | W14: =+B14/'[1]1-COSTO X KM'!B14-1 -> 0.26100341 | X14: =+C14/'[1]1-COSTO X KM'!C14-1 -> 0.48790212 | Y14: =+D14/'[1]1-COSTO X KM'!D14-1 -> 0.49967885 | Z14: =+E14/'[1]1-COSTO X KM'!E14-1 -> 0.41486 | AA14: =+F14/'[1]1-COSTO X KM'!F14-1 -> 0.61324541 | AB14: =+G14/'[1]1-COSTO X KM'!G14-1 -> 0.3089135 | AC14: =+H14/'[1]1-COSTO X KM'!H14-1 -> 0.44588432 | AD14: =+I14/'[1]1-COSTO X KM'!I14-1 -> 0.32356718 | AE14: =+J14/'[1]1-COSTO X KM'!J14-1 -> 0.36065281 | AF14: =+L14 -> 7. SEGURO DEL VEHÍCULO | AG14: =+B14/'[2]1-COSTO X KM'!B14-1 -> 0.18592012 | AH14: =+C14/'[2]1-COSTO X KM'!C14-1 -> 0.23271892 | AI14: =+D14/'[2]1-COSTO X KM'!D14-1 -> 0.24586093 | AJ14: =+E14/'[2]1-COSTO X KM'!E14-1 -> 0.18078277 | AK14: =+F14/'[2]1-COSTO X KM'!F14-1 -> 0.36244767 | AL14: =+G14/'[2]1-COSTO X KM'!G14-1 -> 0.2417412 | AM14: =+H14/'[2]1-COSTO X KM'!H14-1 -> 0.32322724 | AN14: =+I14/'[2]1-COSTO X KM'!I14-1 -> 0.25680765 | AO14: =+J14/'[2]1-COSTO X KM'!J14-1 -> 0.29816116
A15: . Responsabilidad civil | B15: =+'5-PRECIOS SIN IVA'!B27/'2- EMP. REP'!B8 -> 78.828086 | C15: =+'5-PRECIOS SIN IVA'!C27/'2- EMP. REP'!C8 -> 72.575363 | D15: =+'5-PRECIOS SIN IVA'!D27/'2- EMP. REP'!D8 -> 55.010487 | E15: =+'5-PRECIOS SIN IVA'!E27/'2- EMP. REP'!E8 -> 36.260074 | F15: =+'5-PRECIOS SIN IVA'!F27/'2- EMP. REP'!F8 -> 48.212867 | G15: =+'5-PRECIOS SIN IVA'!G27/'2- EMP. REP'!G8 -> 64.977702 | H15: =+'5-PRECIOS SIN IVA'!H27/'2- EMP. REP'!H8 -> 47.711569 | I15: =+'5-PRECIOS SIN IVA'!I27/'2- EMP. REP'!I8 -> 70.187009 | J15: =+'5-PRECIOS SIN IVA'!J27/'2- EMP. REP'!J8 -> 65.210322 | L15: =+A15 -> . Responsabilidad civil | V15: =+A15 -> . Responsabilidad civil | AF15: =+L15 -> . Responsabilidad civil
A16: . Costo de Franquicia | B16: =+'5-PRECIOS SIN IVA'!B29/'2- EMP. REP'!B8 -> 78.828086 | C16: =+'5-PRECIOS SIN IVA'!C29/'2- EMP. REP'!C8 -> 72.575363 | D16: =+'5-PRECIOS SIN IVA'!D29/'2- EMP. REP'!D8 -> 55.010487 | E16: =+'5-PRECIOS SIN IVA'!E29/'2- EMP. REP'!E8 -> 36.260074 | F16: =+'5-PRECIOS SIN IVA'!F29/'2- EMP. REP'!F8 -> 48.212867 | G16: =+'5-PRECIOS SIN IVA'!G29/'2- EMP. REP'!G8 -> 64.977702 | H16: =+'5-PRECIOS SIN IVA'!H29/'2- EMP. REP'!H8 -> 47.711569 | I16: =+'5-PRECIOS SIN IVA'!I29/'2- EMP. REP'!I8 -> 70.187009 | J16: =+'5-PRECIOS SIN IVA'!J29/'2- EMP. REP'!J8 -> 65.210322 | L16: =+A16 -> . Costo de Franquicia | V16: =+A16 -> . Costo de Franquicia | AF16: =+L16 -> . Costo de Franquicia
A17: . Chasis | B17: =+'5-PRECIOS SIN IVA'!B34/'2- EMP. REP'!B8 -> 34.663591 | C17: =+'5-PRECIOS SIN IVA'!C34/'2- EMP. REP'!C8 -> 31.91404 | D17: =+'5-PRECIOS SIN IVA'!D34/'2- EMP. REP'!D8 -> 24.190122 | E17: =+'5-PRECIOS SIN IVA'!E34/'2- EMP. REP'!E8 -> 20.57586 | F17: =+'5-PRECIOS SIN IVA'!F34/'2- EMP. REP'!F8 -> 21.20096 | G17: =+'5-PRECIOS SIN IVA'!G34/'2- EMP. REP'!G8 -> 28.573071 | H17: =+'5-PRECIOS SIN IVA'!H34/'2- EMP. REP'!H8 -> 20.980521 | I17: =+'5-PRECIOS SIN IVA'!I34/'2- EMP. REP'!I8 -> 26.716743 | J17: =+'5-PRECIOS SIN IVA'!J34/'2- EMP. REP'!J8 -> 24.822364 | L17: =+A17 -> . Chasis | V17: =+A17 -> . Chasis | AF17: =+L17 -> . Chasis
A18: . Carrocería | B18: =+'5-PRECIOS SIN IVA'!B35/'2- EMP. REP'!B8 -> 15.065405 | C18: =+'5-PRECIOS SIN IVA'!C35/'2- EMP. REP'!C8 -> 13.870402 | D18: =+'5-PRECIOS SIN IVA'!D35/'2- EMP. REP'!D8 -> 10.513451 | E18: =+'5-PRECIOS SIN IVA'!E35/'2- EMP. REP'!E8 -> 11.227634 | F18: =+'5-PRECIOS SIN IVA'!F35/'2- EMP. REP'!F8 -> 9.214309 | G18: =+'5-PRECIOS SIN IVA'!G35/'2- EMP. REP'!G8 -> 12.418358 | H18: =+'5-PRECIOS SIN IVA'!H35/'2- EMP. REP'!H8 -> 9.1185024 | I18: =+'5-PRECIOS SIN IVA'!I35/'2- EMP. REP'!I8 -> 11.605557 | J18: =+'5-PRECIOS SIN IVA'!J35/'2- EMP. REP'!J8 -> 10.782653 | L18: =+A18 -> . Carrocería | V18: =+A18 -> . Carrocería | AF18: =+L18 -> . Carrocería
A19: 8. PATENTES Y TNFT | B19: =+('5-PRECIOS SIN IVA'!B36+'5-PRECIOS SIN IVA'!B37)/'2- EMP. REP'!B8 -> 1.0760856 | C19: =+('5-PRECIOS SIN IVA'!C36+'5-PRECIOS SIN IVA'!C37)/'2- EMP. REP'!C8 -> 1.0331299 | D19: =+('5-PRECIOS SIN IVA'!D36+'5-PRECIOS SIN IVA'!D37)/'2- EMP. REP'!D8 -> 0.78308917 | E19: =+('5-PRECIOS SIN IVA'!E36+'5-PRECIOS SIN IVA'!E37)/'2- EMP. REP'!E8 -> 0.51617197 | F19: =+('5-PRECIOS SIN IVA'!F36+'5-PRECIOS SIN IVA'!F37)/'2- EMP. REP'!F8 -> 0.6863232 | G19: =+('5-PRECIOS SIN IVA'!G36+'5-PRECIOS SIN IVA'!G37)/'2- EMP. REP'!G8 -> 0.031067929 | H19: =+('5-PRECIOS SIN IVA'!H36+'5-PRECIOS SIN IVA'!H37)/'2- EMP. REP'!H8 -> 0.022812436 | I19: =+('5-PRECIOS SIN IVA'!I36+'5-PRECIOS SIN IVA'!I37)/'2- EMP. REP'!I8 -> 0.033558667 | J19: =+('5-PRECIOS SIN IVA'!J36+'5-PRECIOS SIN IVA'!J37)/'2- EMP. REP'!J8 -> 0.031179153 | L19: =+A19 -> 8. PATENTES Y TNFT | M19: =+B19/B$51 -> 0.00027764446 | N19: =+C19/C$51 -> 0.00029844824 | O19: =+D19/D$51 -> 0.00028085514 | P19: =+E19/E$51 -> 0.000219442 | Q19: =+F19/F$51 -> 0.00028872296 | R19: =+G19/G$51 -> 1.0094313e-05 | S19: =+H19/H$51 -> 9.2167857e-06 | T19: =+I19/I$51 -> 1.0795476e-05 | U19: =+J19/J$51 -> 1.0584879e-05 | V19: =+A19 -> 8. PATENTES Y TNFT | W19: =+B19/'[1]1-COSTO X KM'!B19-1 -> -0.036461882 | X19: =+C19/'[1]1-COSTO X KM'!C19-1 -> 0.1369124 | Y19: =+D19/'[1]1-COSTO X KM'!D19-1 -> 0.14591105 | Z19: =+E19/'[1]1-COSTO X KM'!E19-1 -> 0.066687269 | AA19: =+F19/'[1]1-COSTO X KM'!F19-1 -> 0.23268774 | AB19: =+G19/'[1]1-COSTO X KM'!G19-1 -> 0.00014642168 | AC19: =+H19/'[1]1-COSTO X KM'!H19-1 -> 0.10480641 | AD19: =+I19/'[1]1-COSTO X KM'!I19-1 -> 0.016593738 | AE19: =+J19/'[1]1-COSTO X KM'!J19-1 -> 0.04507814 | AF19: =+L19 -> 8. PATENTES Y TNFT | AG19: =+B19/'[2]1-COSTO X KM'!B19-1 -> -0.043819942 | AH19: =+C19/'[2]1-COSTO X KM'!C19-1 -> -0.0060871408 | AI19: =+D19/'[2]1-COSTO X KM'!D19-1 -> 0.004508955 | AJ19: =+E19/'[2]1-COSTO X KM'!E19-1 -> -0.056579246 | AK19: =+F19/'[2]1-COSTO X KM'!F19-1 -> 0.098510161 | AL19: =+G19/'[2]1-COSTO X KM'!G19-1 -> 0.0011873132 | AM19: =+H19/'[2]1-COSTO X KM'!H19-1 -> 0.066887625 | AN19: =+I19/'[2]1-COSTO X KM'!I19-1 -> 0.016906601 | AO19: =+J19/'[2]1-COSTO X KM'!J19-1 -> 0.050366499
A20: 9. SALARIOS DEL PERSONAL | B20: =SUM(B21:B24) -> 1581.0802 | C20: =SUM(C21:C24) -> 1488.423 | D20: =SUM(D21:D24) -> 1123.2204 | E20: =SUM(E21:E24) -> 779.24119 | F20: =SUM(F21:F24) -> 1003.7772 | G20: =SUM(G21:G24) -> 1339.1591 | H20: =SUM(H21:H24) -> 984.75196 | I20: =SUM(I21:I24) -> 1402.7351 | J20: =SUM(J21:J24) -> 1307.237 | L20: =+A20 -> 9. SALARIOS DEL PERSONAL | M20: =+B20/B$51 -> 0.40793982 | N20: =+C20/C$51 -> 0.42997226 | O20: =+D20/D$51 -> 0.40284331 | P20: =+E20/E$51 -> 0.33128153 | Q20: =+F20/F$51 -> 0.42226976 | R20: =+G20/G$51 -> 0.43510759 | S20: =+H20/H$51 -> 0.39786403 | T20: =+I20/I$51 -> 0.45124535 | U20: =+J20/J$51 -> 0.44378839 | V20: =+A20 -> 9. SALARIOS DEL PERSONAL | W20: =+B20/'[1]1-COSTO X KM'!B20-1 -> 0.3007605 | X20: =+C20/'[1]1-COSTO X KM'!C20-1 -> 0.49913528 | Y20: =+D20/'[1]1-COSTO X KM'!D20-1 -> 0.52387197 | Z20: =+E20/'[1]1-COSTO X KM'!E20-1 -> 0.39501739 | AA20: =+F20/'[1]1-COSTO X KM'!F20-1 -> 0.50244662 | AB20: =+G20/'[1]1-COSTO X KM'!G20-1 -> 0.34080503 | AC20: =+H20/'[1]1-COSTO X KM'!H20-1 -> 0.47708754 | AD20: =+I20/'[1]1-COSTO X KM'!I20-1 -> 0.31139156 | AE20: =+J20/'[1]1-COSTO X KM'!J20-1 -> 0.40270603 | AF20: =+L20 -> 9. SALARIOS DEL PERSONAL | AG20: =+B20/'[2]1-COSTO X KM'!B20-1 -> 0.15009329 | AH20: =+C20/'[2]1-COSTO X KM'!C20-1 -> 0.18853242 | AI20: =+D20/'[2]1-COSTO X KM'!D20-1 -> 0.20392115 | AJ20: =+E20/'[2]1-COSTO X KM'!E20-1 -> 0.131259 | AK20: =+F20/'[2]1-COSTO X KM'!F20-1 -> 0.31289276 | AL20: =+G20/'[2]1-COSTO X KM'!G20-1 -> 0.197073 | AM20: =+H20/'[2]1-COSTO X KM'!H20-1 -> 0.27519254 | AN20: =+I20/'[2]1-COSTO X KM'!I20-1 -> 0.19587004 | AO20: =+J20/'[2]1-COSTO X KM'!J20-1 -> 0.25576395
A21: Personal de conducción | B21: =+'4- PERSONAL'!B138/'2- EMP. REP'!B8 -> 1279.4083 | C21: =+'4- PERSONAL'!C138/'2- EMP. REP'!C8 -> 1207.4801 | D21: =+'4- PERSONAL'!D138/'2- EMP. REP'!D8 -> 910.27209 | E21: =+'4- PERSONAL'!E138/'2- EMP. REP'!E8 -> 625.69666 | F21: =+'4- PERSONAL'!F138/'2- EMP. REP'!F8 -> 817.1428 | G21: =+'4- PERSONAL'!G138/'2- EMP. REP'!G8 -> 1087.6272 | H21: =+'4- PERSONAL'!H138/'2- EMP. REP'!H8 -> 800.05814 | I21: =+'4- PERSONAL'!I138/'2- EMP. REP'!I8 -> 1134.1255 | J21: =+'4- PERSONAL'!J138/'2- EMP. REP'!J8 -> 1057.6735 | L21: =+A21 -> Personal de conducción | V21: =+A21 -> Personal de conducción | AF21: =+L21 -> Personal de conducción
A22: Personal de tráfico | B22: =+'4- PERSONAL'!B139/'2- EMP. REP'!B8 -> 110.86749 | C22: =+'4- PERSONAL'!C139/'2- EMP. REP'!C8 -> 90.100612 | D22: =+'4- PERSONAL'!D139/'2- EMP. REP'!D8 -> 68.29423 | E22: =+'4- PERSONAL'!E139/'2- EMP. REP'!E8 -> 49.242951 | F22: =+'4- PERSONAL'!F139/'2- EMP. REP'!F8 -> 59.855144 | G22: =+'4- PERSONAL'!G139/'2- EMP. REP'!G8 -> 80.668294 | H22: =+'4- PERSONAL'!H139/'2- EMP. REP'!H8 -> 59.232795 | I22: =+'4- PERSONAL'!I139/'2- EMP. REP'!I8 -> 98.716808 | J22: =+'4- PERSONAL'!J139/'2- EMP. REP'!J8 -> 91.717185 | L22: =+A22 -> Personal de tráfico | V22: =+A22 -> Personal de tráfico | AF22: =+L22 -> Personal de tráfico
A23: Personal de mantenimiento | B23: =+'4- PERSONAL'!B140/'2- EMP. REP'!B8 -> 120.22468 | C23: =+'4- PERSONAL'!C140/'2- EMP. REP'!C8 -> 122.0717 | D23: =+'4- PERSONAL'!D140/'2- EMP. REP'!D8 -> 92.527591 | E23: =+'4- PERSONAL'!E140/'2- EMP. REP'!E8 -> 66.716201 | F23: =+'4- PERSONAL'!F140/'2- EMP. REP'!F8 -> 81.094 | G23: =+'4- PERSONAL'!G140/'2- EMP. REP'!G8 -> 109.2924 | H23: =+'4- PERSONAL'!H140/'2- EMP. REP'!H8 -> 80.250791 | I23: =+'4- PERSONAL'!I140/'2- EMP. REP'!I8 -> 107.04846 | J23: =+'4- PERSONAL'!J140/'2- EMP. REP'!J8 -> 99.458075 | L23: =+A23 -> Personal de mantenimiento | V23: =+A23 -> Personal de mantenimiento | AF23: =+L23 -> Personal de mantenimiento
A24: Personal de administración | B24: =+'4- PERSONAL'!B141/'2- EMP. REP'!B8 -> 70.579775 | C24: =+'4- PERSONAL'!C141/'2- EMP. REP'!C8 -> 68.770549 | D24: =+'4- PERSONAL'!D141/'2- EMP. REP'!D8 -> 52.126524 | E24: =+'4- PERSONAL'!E141/'2- EMP. REP'!E8 -> 37.585369 | F24: =+'4- PERSONAL'!F141/'2- EMP. REP'!F8 -> 45.685273 | G24: =+'4- PERSONAL'!G141/'2- EMP. REP'!G8 -> 61.571175 | H24: =+'4- PERSONAL'!H141/'2- EMP. REP'!H8 -> 45.210238 | I24: =+'4- PERSONAL'!I141/'2- EMP. REP'!I8 -> 62.844334 | J24: =+'4- PERSONAL'!J141/'2- EMP. REP'!J8 -> 58.388288 | L24: =+A24 -> Personal de administración | V24: =+A24 -> Personal de administración | AF24: =+L24 -> Personal de administración
A25: 10. SEGUROS DEL PERSONAL | B25: =+'4- PERSONAL'!B132/'2- EMP. REP'!B5 -> 81.436904 | C25: =+'4- PERSONAL'!C132/'2- EMP. REP'!C5 -> 76.663343 | D25: =+'4- PERSONAL'!D132/'2- EMP. REP'!D5 -> 57.851228 | E25: =+'4- PERSONAL'!E132/'2- EMP. REP'!E5 -> 40.135288 | F25: =+'4- PERSONAL'!F132/'2- EMP. REP'!F5 -> 51.708034 | G25: =+'4- PERSONAL'!G132/'2- EMP. REP'!G5 -> 68.977672 | H25: =+'4- PERSONAL'!H132/'2- EMP. REP'!H5 -> 50.722166 | I25: =+'4- PERSONAL'!I132/'2- EMP. REP'!I5 -> 72.253726 | J25: =+'4- PERSONAL'!J132/'2- EMP. REP'!J5 -> 67.339255 | L25: =+A25 -> 10. SEGUROS DEL PERSONAL | M25: =+B25/B$51 -> 0.02101181 | N25: =+C25/C$51 -> 0.022146333 | O25: =+D25/D$51 -> 0.020748358 | P25: =+E25/E$51 -> 0.017062855 | Q25: =+F25/F$51 -> 0.021752575 | R25: =+G25/G$51 -> 0.022411607 | S25: =+H25/H$51 -> 0.020493004 | T25: =+I25/I$51 -> 0.023243276 | U25: =+J25/J$51 -> 0.02286072 | V25: =+A25 -> 10. SEGUROS DEL PERSONAL | W25: =+B25/'[1]1-COSTO X KM'!B25-1 -> 0.30083186 | X25: =+C25/'[1]1-COSTO X KM'!C25-1 -> 0.4992198 | Y25: =+D25/'[1]1-COSTO X KM'!D25-1 -> 0.52397327 | Z25: =+E25/'[1]1-COSTO X KM'!E25-1 -> 0.39510682 | AA25: =+F25/'[1]1-COSTO X KM'!F25-1 -> 0.50249582 | AB25: =+G25/'[1]1-COSTO X KM'!G25-1 -> 0.34085948 | AC25: =+H25/'[1]1-COSTO X KM'!H25-1 -> 0.47714531 | AD25: =+I25/'[1]1-COSTO X KM'!I25-1 -> 0.31144184 | AE25: =+J25/'[1]1-COSTO X KM'!J25-1 -> 0.40269892 | AF25: =+L25 -> 10. SEGUROS DEL PERSONAL | AG25: =+B25/'[2]1-COSTO X KM'!B25-1 -> 0.15007523 | AH25: =+C25/'[2]1-COSTO X KM'!C25-1 -> 0.1885193 | AI25: =+D25/'[2]1-COSTO X KM'!D25-1 -> 0.2039155 | AJ25: =+E25/'[2]1-COSTO X KM'!E25-1 -> 0.13125225 | AK25: =+F25/'[2]1-COSTO X KM'!F25-1 -> 0.31284473 | AL25: =+G25/'[2]1-COSTO X KM'!G25-1 -> 0.19704865 | AM25: =+H25/'[2]1-COSTO X KM'!H25-1 -> 0.27516288 | AN25: =+I25/'[2]1-COSTO X KM'!I25-1 -> 0.19584244 | AO25: =+J25/'[2]1-COSTO X KM'!J25-1 -> 0.25569937
A26: 11. MÁQUINAS, HERRAMIENTAS E INMUEBLES | B26: =SUM(B27:B30) -> 13.424851 | C26: =SUM(C27:C30) -> 12.359978 | D26: =SUM(D27:D30) -> 9.3685846 | E26: =SUM(E27:E30) -> 7.7027731 | F26: =SUM(F27:F30) -> 7.8764877 | G26: =SUM(G27:G30) -> 10.615342 | H26: =SUM(H27:H30) -> 7.7945912 | I26: =SUM(I27:I30) -> 10.592917 | J26: =SUM(J27:J30) -> 9.8418146 | L26: =+A26 -> 11. MÁQUINAS, HERRAMIENTAS E INMUEBLES | M26: =+B26/B$51 -> 0.003463791 | N26: =+C26/C$51 -> 0.0035705226 | O26: =+D26/D$51 -> 0.0033600454 | P26: =+E26/E$51 -> 0.0032747069 | Q26: =+F26/F$51 -> 0.0033134868 | R26: =+G26/G$51 -> 0.0034490418 | S26: =+H26/H$51 -> 0.0031492067 | T26: =+I26/I$51 -> 0.0034076317 | U26: =+J26/J$51 -> 0.0033411562 | V26: =+A26 -> 11. MÁQUINAS, HERRAMIENTAS E INMUEBLES | W26: =+B26/'[1]1-COSTO X KM'!B26-1 -> 0.34462516 | X26: =+C26/'[1]1-COSTO X KM'!C26-1 -> 0.58657036 | Y26: =+D26/'[1]1-COSTO X KM'!D26-1 -> 0.59912805 | Z26: =+E26/'[1]1-COSTO X KM'!E26-1 -> 0.50910412 | AA26: =+F26/'[1]1-COSTO X KM'!F26-1 -> 0.70519828 | AB26: =+G26/'[1]1-COSTO X KM'!G26-1 -> 0.38351985 | AC26: =+H26/'[1]1-COSTO X KM'!H26-1 -> 0.52829783 | AD26: =+I26/'[1]1-COSTO X KM'!I26-1 -> 0.3938983 | AE26: =+J26/'[1]1-COSTO X KM'!J26-1 -> 0.43295457 | AF26: =+L26 -> 11. MÁQUINAS, HERRAMIENTAS E INMUEBLES | AG26: =+B26/'[2]1-COSTO X KM'!B26-1 -> 0.23819836 | AH26: =+C26/'[2]1-COSTO X KM'!C26-1 -> 0.28706018 | AI26: =+D26/'[2]1-COSTO X KM'!D26-1 -> 0.30078151 | AJ26: =+E26/'[2]1-COSTO X KM'!E26-1 -> 0.23282665 | AK26: =+F26/'[2]1-COSTO X KM'!F26-1 -> 0.40841014 | AL26: =+G26/'[2]1-COSTO X KM'!G26-1 -> 0.28363161 | AM26: =+H26/'[2]1-COSTO X KM'!H26-1 -> 0.36786659 | AN26: =+I26/'[2]1-COSTO X KM'!I26-1 -> 0.29570948 | AO26: =+J26/'[2]1-COSTO X KM'!J26-1 -> 0.338343
A27: Conservación de inmuebles | B27: =+('3- REND Y CONS'!B33*'3- REND Y CONS'!B38*'5-PRECIOS SIN IVA'!B43+'3- REND Y CONS'!B37*SUMPRODUCT('3- REND Y CONS'!B34:B35,'5-PRECIOS SIN IVA'!B44:B45))/'2- EMP. REP'!B5 -> 2.435158 | C27: =+('3- REND Y CONS'!C33*'3- REND Y CONS'!C38*'5-PRECIOS SIN IVA'!C43+'3- REND Y CONS'!C37*SUMPRODUCT('3- REND Y CONS'!C34:C35,'5-PRECIOS SIN IVA'!C44:C45))/'2- EMP. REP'!C5 -> 2.2419989 | D27: =+('3- REND Y CONS'!D33*'3- REND Y CONS'!D38*'5-PRECIOS SIN IVA'!D43+'3- REND Y CONS'!D37*SUMPRODUCT('3- REND Y CONS'!D34:D35,'5-PRECIOS SIN IVA'!D44:D45))/'2- EMP. REP'!D5 -> 1.6993845 | E27: =+('3- REND Y CONS'!E33*'3- REND Y CONS'!E38*'5-PRECIOS SIN IVA'!E43+'3- REND Y CONS'!E37*SUMPRODUCT('3- REND Y CONS'!E34:E35,'5-PRECIOS SIN IVA'!E44:E45))/'2- EMP. REP'!E5 -> 1.2011513 | F27: =+('3- REND Y CONS'!F33*'3- REND Y CONS'!F38*'5-PRECIOS SIN IVA'!F43+'3- REND Y CONS'!F37*SUMPRODUCT('3- REND Y CONS'!F34:F35,'5-PRECIOS SIN IVA'!F44:F45))/'2- EMP. REP'!F5 -> 1.3275737 | G27: =+('3- REND Y CONS'!G33*'3- REND Y CONS'!G38*'5-PRECIOS SIN IVA'!G43+'3- REND Y CONS'!G37*SUMPRODUCT('3- REND Y CONS'!G34:G35,'5-PRECIOS SIN IVA'!G44:G45))/'2- EMP. REP'!G5 -> 1.7892047 | H27: =+('3- REND Y CONS'!H33*'3- REND Y CONS'!H38*'5-PRECIOS SIN IVA'!H43+'3- REND Y CONS'!H37*SUMPRODUCT('3- REND Y CONS'!H34:H35,'5-PRECIOS SIN IVA'!H44:H45))/'2- EMP. REP'!H5 -> 1.3137701 | I27: =+('3- REND Y CONS'!I33*'3- REND Y CONS'!I38*'5-PRECIOS SIN IVA'!I43+'3- REND Y CONS'!I37*SUMPRODUCT('3- REND Y CONS'!I34:I35,'5-PRECIOS SIN IVA'!I44:I45))/'2- EMP. REP'!I5 -> 1.9326465 | J27: =+('3- REND Y CONS'!J33*'3- REND Y CONS'!J38*'5-PRECIOS SIN IVA'!J43+'3- REND Y CONS'!J37*SUMPRODUCT('3- REND Y CONS'!J34:J35,'5-PRECIOS SIN IVA'!J44:J45))/'2- EMP. REP'!J5 -> 1.7956101 | L27: =+A27 -> Conservación de inmuebles | V27: =+A27 -> Conservación de inmuebles | AF27: =+L27 -> Conservación de inmuebles
A28: Depreciación de inmuebles | B28: =+((('3- REND Y CONS'!B34*'5-PRECIOS SIN IVA'!B44+'3- REND Y CONS'!B35*'5-PRECIOS SIN IVA'!B45)*(1-'3- REND Y CONS'!B43))/'3- REND Y CONS'!B39+(('3- REND Y CONS'!B33*'5-PRECIOS SIN IVA'!B43)*(1-'3- REND Y CONS'!B44))/'3- REND Y CONS'!B41)/'2- EMP. REP'!B5 -> 3.696107 | C28: =+((('3- REND Y CONS'!C34*'5-PRECIOS SIN IVA'!C44+'3- REND Y CONS'!C35*'5-PRECIOS SIN IVA'!C45)*(1-'3- REND Y CONS'!C43))/'3- REND Y CONS'!C39+(('3- REND Y CONS'!C33*'5-PRECIOS SIN IVA'!C43)*(1-'3- REND Y CONS'!C44))/'3- REND Y CONS'!C41)/'2- EMP. REP'!C5 -> 3.4029281 | D28: =+((('3- REND Y CONS'!D34*'5-PRECIOS SIN IVA'!D44+'3- REND Y CONS'!D35*'5-PRECIOS SIN IVA'!D45)*(1-'3- REND Y CONS'!D43))/'3- REND Y CONS'!D39+(('3- REND Y CONS'!D33*'5-PRECIOS SIN IVA'!D43)*(1-'3- REND Y CONS'!D44))/'3- REND Y CONS'!D41)/'2- EMP. REP'!D5 -> 2.5793427 | E28: =+((('3- REND Y CONS'!E34*'5-PRECIOS SIN IVA'!E44+'3- REND Y CONS'!E35*'5-PRECIOS SIN IVA'!E45)*(1-'3- REND Y CONS'!E43))/'3- REND Y CONS'!E39+(('3- REND Y CONS'!E33*'5-PRECIOS SIN IVA'!E43)*(1-'3- REND Y CONS'!E44))/'3- REND Y CONS'!E41)/'2- EMP. REP'!E5 -> 1.8371093 | F28: =+((('3- REND Y CONS'!F34*'5-PRECIOS SIN IVA'!F44+'3- REND Y CONS'!F35*'5-PRECIOS SIN IVA'!F45)*(1-'3- REND Y CONS'!F43))/'3- REND Y CONS'!F39+(('3- REND Y CONS'!F33*'5-PRECIOS SIN IVA'!F43)*(1-'3- REND Y CONS'!F44))/'3- REND Y CONS'!F41)/'2- EMP. REP'!F5 -> 2.0880079 | G28: =+((('3- REND Y CONS'!G34*'5-PRECIOS SIN IVA'!G44+'3- REND Y CONS'!G35*'5-PRECIOS SIN IVA'!G45)*(1-'3- REND Y CONS'!G43))/'3- REND Y CONS'!G39+(('3- REND Y CONS'!G33*'5-PRECIOS SIN IVA'!G43)*(1-'3- REND Y CONS'!G44))/'3- REND Y CONS'!G41)/'2- EMP. REP'!G5 -> 2.8140611 | H28: =+((('3- REND Y CONS'!H34*'5-PRECIOS SIN IVA'!H44+'3- REND Y CONS'!H35*'5-PRECIOS SIN IVA'!H45)*(1-'3- REND Y CONS'!H43))/'3- REND Y CONS'!H39+(('3- REND Y CONS'!H33*'5-PRECIOS SIN IVA'!H43)*(1-'3- REND Y CONS'!H44))/'3- REND Y CONS'!H41)/'2- EMP. REP'!H5 -> 2.0662976 | I28: =+((('3- REND Y CONS'!I34*'5-PRECIOS SIN IVA'!I44+'3- REND Y CONS'!I35*'5-PRECIOS SIN IVA'!I45)*(1-'3- REND Y CONS'!I43))/'3- REND Y CONS'!I39+(('3- REND Y CONS'!I33*'5-PRECIOS SIN IVA'!I43)*(1-'3- REND Y CONS'!I44))/'3- REND Y CONS'!I41)/'2- EMP. REP'!I5 -> 3.0396664 | J28: =+((('3- REND Y CONS'!J34*'5-PRECIOS SIN IVA'!J44+'3- REND Y CONS'!J35*'5-PRECIOS SIN IVA'!J45)*(1-'3- REND Y CONS'!J43))/'3- REND Y CONS'!J39+(('3- REND Y CONS'!J33*'5-PRECIOS SIN IVA'!J43)*(1-'3- REND Y CONS'!J44))/'3- REND Y CONS'!J41)/'2- EMP. REP'!J5 -> 2.8241355 | L28: =+A28 -> Depreciación de inmuebles | V28: =+A28 -> Depreciación de inmuebles | AF28: =+L28 -> Depreciación de inmuebles
A29: Conservación de máquinas y herramientas | B29: =+('5-PRECIOS SIN IVA'!B17+'5-PRECIOS SIN IVA'!B18)*('3- REND Y CONS'!B45)*('3- REND Y CONS'!B46)/'2- EMP. REP'!B8 -> 1.9891598 | C29: =+('5-PRECIOS SIN IVA'!C17+'5-PRECIOS SIN IVA'!C18)*('3- REND Y CONS'!C45)*('3- REND Y CONS'!C46)/'2- EMP. REP'!C8 -> 1.8313777 | D29: =+('5-PRECIOS SIN IVA'!D17+'5-PRECIOS SIN IVA'!D18)*('3- REND Y CONS'!D45)*('3- REND Y CONS'!D46)/'2- EMP. REP'!D8 -> 1.3881429 | E29: =+('5-PRECIOS SIN IVA'!E17+'5-PRECIOS SIN IVA'!E18)*('3- REND Y CONS'!E45)*('3- REND Y CONS'!E46)/'2- EMP. REP'!E8 -> 1.2721398 | F29: =+('5-PRECIOS SIN IVA'!F17+'5-PRECIOS SIN IVA'!F18)*('3- REND Y CONS'!F45)*('3- REND Y CONS'!F46)/'2- EMP. REP'!F8 -> 1.2166108 | G29: =+('5-PRECIOS SIN IVA'!G17+'5-PRECIOS SIN IVA'!G18)*('3- REND Y CONS'!G45)*('3- REND Y CONS'!G46)/'2- EMP. REP'!G8 -> 1.6396571 | H29: =+('5-PRECIOS SIN IVA'!H17+'5-PRECIOS SIN IVA'!H18)*('3- REND Y CONS'!H45)*('3- REND Y CONS'!H46)/'2- EMP. REP'!H8 -> 1.2039609 | I29: =+('5-PRECIOS SIN IVA'!I17+'5-PRECIOS SIN IVA'!I18)*('3- REND Y CONS'!I45)*('3- REND Y CONS'!I46)/'2- EMP. REP'!I8 -> 1.532892 | J29: =+('5-PRECIOS SIN IVA'!J17+'5-PRECIOS SIN IVA'!J18)*('3- REND Y CONS'!J45)*('3- REND Y CONS'!J46)/'2- EMP. REP'!J8 -> 1.4242006 | L29: =+A29 -> Conservación de máquinas y herramientas | V29: =+A29 -> Conservación de máquinas y herramientas | AF29: =+L29 -> Conservación de máquinas y herramientas
A30: Depreciación de máquinas y herramientas | B30: =+('3- REND Y CONS'!B45*'2- EMP. REP'!B6*('5-PRECIOS SIN IVA'!B17+'5-PRECIOS SIN IVA'!B18)*(1-'3- REND Y CONS'!B48)/'3- REND Y CONS'!B47)/'2- EMP. REP'!B5 -> 5.3044262 | C30: =+('3- REND Y CONS'!C45*'2- EMP. REP'!C6*('5-PRECIOS SIN IVA'!C17+'5-PRECIOS SIN IVA'!C18)*(1-'3- REND Y CONS'!C48)/'3- REND Y CONS'!C47)/'2- EMP. REP'!C5 -> 4.8836738 | D30: =+('3- REND Y CONS'!D45*'2- EMP. REP'!D6*('5-PRECIOS SIN IVA'!D17+'5-PRECIOS SIN IVA'!D18)*(1-'3- REND Y CONS'!D48)/'3- REND Y CONS'!D47)/'2- EMP. REP'!D5 -> 3.7017145 | E30: =+('3- REND Y CONS'!E45*'2- EMP. REP'!E6*('5-PRECIOS SIN IVA'!E17+'5-PRECIOS SIN IVA'!E18)*(1-'3- REND Y CONS'!E48)/'3- REND Y CONS'!E47)/'2- EMP. REP'!E5 -> 3.3923727 | F30: =+('3- REND Y CONS'!F45*'2- EMP. REP'!F6*('5-PRECIOS SIN IVA'!F17+'5-PRECIOS SIN IVA'!F18)*(1-'3- REND Y CONS'!F48)/'3- REND Y CONS'!F47)/'2- EMP. REP'!F5 -> 3.2442953 | G30: =+('3- REND Y CONS'!G45*'2- EMP. REP'!G6*('5-PRECIOS SIN IVA'!G17+'5-PRECIOS SIN IVA'!G18)*(1-'3- REND Y CONS'!G48)/'3- REND Y CONS'!G47)/'2- EMP. REP'!G5 -> 4.372419 | H30: =+('3- REND Y CONS'!H45*'2- EMP. REP'!H6*('5-PRECIOS SIN IVA'!H17+'5-PRECIOS SIN IVA'!H18)*(1-'3- REND Y CONS'!H48)/'3- REND Y CONS'!H47)/'2- EMP. REP'!H5 -> 3.2105625 | I30: =+('3- REND Y CONS'!I45*'2- EMP. REP'!I6*('5-PRECIOS SIN IVA'!I17+'5-PRECIOS SIN IVA'!I18)*(1-'3- REND Y CONS'!I48)/'3- REND Y CONS'!I47)/'2- EMP. REP'!I5 -> 4.0877121 | J30: =+('3- REND Y CONS'!J45*'2- EMP. REP'!J6*('5-PRECIOS SIN IVA'!J17+'5-PRECIOS SIN IVA'!J18)*(1-'3- REND Y CONS'!J48)/'3- REND Y CONS'!J47)/'2- EMP. REP'!J5 -> 3.7978684 | L30: =+A30 -> Depreciación de máquinas y herramientas | V30: =+A30 -> Depreciación de máquinas y herramientas | AF30: =+L30 -> Depreciación de máquinas y herramientas
A31: 12. IMPUESTOS Y TASAS MUNICIPALES | B31: =(SUMPRODUCT('3- REND Y CONS'!B33:B36,'5-PRECIOS SIN IVA'!B43:B46)*'5-PRECIOS SIN IVA'!B52)*(SUM('5-PRECIOS SIN IVA'!B55:B57))/'2- EMP. REP'!B5 -> 2.6264971 | C31: =(SUMPRODUCT('3- REND Y CONS'!C33:C36,'5-PRECIOS SIN IVA'!C43:C46)*'5-PRECIOS SIN IVA'!C52)*(SUM('5-PRECIOS SIN IVA'!C55:C57))/'2- EMP. REP'!C5 -> 2.4181607 | D31: =(SUMPRODUCT('3- REND Y CONS'!D33:D36,'5-PRECIOS SIN IVA'!D43:D46)*'5-PRECIOS SIN IVA'!D52)*(SUM('5-PRECIOS SIN IVA'!D55:D57))/'2- EMP. REP'!D5 -> 1.8329112 | E31: =(SUMPRODUCT('3- REND Y CONS'!E33:E36,'5-PRECIOS SIN IVA'!E43:E46)*'5-PRECIOS SIN IVA'!E52)*(SUM('5-PRECIOS SIN IVA'!E55:E57))/'2- EMP. REP'!E5 -> 1.3096185 | F31: =(SUMPRODUCT('3- REND Y CONS'!F33:F36,'5-PRECIOS SIN IVA'!F43:F46)*'5-PRECIOS SIN IVA'!F52)*(SUM('5-PRECIOS SIN IVA'!F55:F57))/'2- EMP. REP'!F5 -> 1.2218363 | G31: =(SUMPRODUCT('3- REND Y CONS'!G33:G36,'5-PRECIOS SIN IVA'!G43:G46)*'5-PRECIOS SIN IVA'!G52)*(SUM('5-PRECIOS SIN IVA'!G55:G57))/'2- EMP. REP'!G5 -> 1.6466997 | H31: =(SUMPRODUCT('3- REND Y CONS'!H33:H36,'5-PRECIOS SIN IVA'!H43:H46)*'5-PRECIOS SIN IVA'!H52)*(SUM('5-PRECIOS SIN IVA'!H55:H57))/'2- EMP. REP'!H5 -> 1.2091321 | I31: =(SUMPRODUCT('3- REND Y CONS'!I33:I36,'5-PRECIOS SIN IVA'!I43:I46)*'5-PRECIOS SIN IVA'!I52)*(SUM('5-PRECIOS SIN IVA'!I55:I57))/'2- EMP. REP'!I5 -> 1.7787168 | J31: =(SUMPRODUCT('3- REND Y CONS'!J33:J36,'5-PRECIOS SIN IVA'!J43:J46)*'5-PRECIOS SIN IVA'!J52)*(SUM('5-PRECIOS SIN IVA'!J55:J57))/'2- EMP. REP'!J5 -> 1.6525949 | L31: =+A31 -> 12. IMPUESTOS Y TASAS MUNICIPALES | M31: =+B31/B$51 -> 0.00067767135 | N31: =+C31/C$51 -> 0.00069855279 | O31: =+D31/D$51 -> 0.0006573741 | P31: =+E31/E$51 -> 0.00055676271 | Q31: =+F31/F$51 -> 0.00051400302 | R31: =+G31/G$51 -> 0.00053503093 | S31: =+H31/H$51 -> 0.00048851915 | T31: =+I31/I$51 -> 0.00057219477 | U31: =+J31/J$51 -> 0.0005610325 | V31: =+A31 -> 12. IMPUESTOS Y TASAS MUNICIPALES | W31: =+B31/'[1]1-COSTO X KM'!B31-1 -> -0.21901887 | X31: =+C31/'[1]1-COSTO X KM'!C31-1 -> 0.41821785 | Y31: =+D31/'[1]1-COSTO X KM'!D31-1 -> 0.42944302 | Z31: =+E31/'[1]1-COSTO X KM'!E31-1 -> 0.33061696 | AA31: =+F31/'[1]1-COSTO X KM'!F31-1 -> 0.40840268 | AB31: =+G31/'[1]1-COSTO X KM'!G31-1 -> 0.14271349 | AC31: =+H31/'[1]1-COSTO X KM'!H31-1 -> 0.26229236 | AD31: =+I31/'[1]1-COSTO X KM'!I31-1 -> 0.1615053 | AE31: =+J31/'[1]1-COSTO X KM'!J31-1 -> 0.19405005 | AF31: =+L31 -> 12. IMPUESTOS Y TASAS MUNICIPALES | AG31: =+B31/'[2]1-COSTO X KM'!B31-1 -> -0.25430682 | AH31: =+C31/'[2]1-COSTO X KM'!C31-1 -> 0.19292491 | AI31: =+D31/'[2]1-COSTO X KM'!D31-1 -> 0.20564267 | AJ31: =+E31/'[2]1-COSTO X KM'!E31-1 -> 0.13232272 | AK31: =+F31/'[2]1-COSTO X KM'!F31-1 -> 0.20760998 | AL31: =+G31/'[2]1-COSTO X KM'!G31-1 -> 0.1006214 | AM31: =+H31/'[2]1-COSTO X KM'!H31-1 -> 0.17284681 | AN31: =+I31/'[2]1-COSTO X KM'!I31-1 -> 0.11790186 | AO31: =+J31/'[2]1-COSTO X KM'!J31-1 -> 0.15468487
A32: 13. COSTO DEL CAPITAL INVERTIDO | B32: =SUM(B33:B36) -> 139.01445 | C32: =SUM(C33:C36) -> 127.98768 | D32: =SUM(D33:D36) -> 97.011773 | E32: =SUM(E33:E36) -> 85.776594 | F32: =SUM(F33:F36) -> 81.527812 | G32: =SUM(G33:G36) -> 109.8771 | H32: =SUM(H33:H36) -> 80.680119 | I32: =SUM(I33:I36) -> 104.72111 | J32: =SUM(J33:J36) -> 97.295747 | L32: =+A32 -> 13. COSTO DEL CAPITAL INVERTIDO | M32: =+B32/B$51 -> 0.035867585 | N32: =+C32/C$51 -> 0.036972792 | O32: =+D32/D$51 -> 0.034793299 | P32: =+E32/E$51 -> 0.036466504 | Q32: =+F32/F$51 -> 0.034297181 | R32: =+G32/G$51 -> 0.035700282 | S32: =+H32/H$51 -> 0.032596754 | T32: =+I32/I$51 -> 0.033687697 | U32: =+J32/J$51 -> 0.033030524 | V32: =+A32 -> 13. COSTO DEL CAPITAL INVERTIDO | W32: =+B32/'[1]1-COSTO X KM'!B32-1 -> 0.28380747 | X32: =+C32/'[1]1-COSTO X KM'!C32-1 -> 0.69609499 | Y32: =+D32/'[1]1-COSTO X KM'!D32-1 -> 0.70951956 | Z32: =+E32/'[1]1-COSTO X KM'!E32-1 -> 0.6027828 | AA32: =+F32/'[1]1-COSTO X KM'!F32-1 -> 0.8270007 | AB32: =+G32/'[1]1-COSTO X KM'!G32-1 -> 0.48234476 | AC32: =+H32/'[1]1-COSTO X KM'!H32-1 -> 0.63746424 | AD32: =+I32/'[1]1-COSTO X KM'!I32-1 -> 0.49794982 | AE32: =+J32/'[1]1-COSTO X KM'!J32-1 -> 0.53992156 | AF32: =+L32 -> 13. COSTO DEL CAPITAL INVERTIDO | AG32: =+B32/'[2]1-COSTO X KM'!B32-1 -> 0.16258521 | AH32: =+C32/'[2]1-COSTO X KM'!C32-1 -> 0.34478702 | AI32: =+D32/'[2]1-COSTO X KM'!D32-1 -> 0.35912378 | AJ32: =+E32/'[2]1-COSTO X KM'!E32-1 -> 0.28242379 | AK32: =+F32/'[2]1-COSTO X KM'!F32-1 -> 0.47357801 | AL32: =+G32/'[2]1-COSTO X KM'!G32-1 -> 0.34302591 | AM32: =+H32/'[2]1-COSTO X KM'!H32-1 -> 0.43115849 | AN32: =+I32/'[2]1-COSTO X KM'!I32-1 -> 0.35816881 | AO32: =+J32/'[2]1-COSTO X KM'!J32-1 -> 0.40285747
A33: . Chasis (incluye boletera y rampa) | B33: =+'5-PRECIOS SIN IVA'!B39*'2- EMP. REP'!B6*('5-PRECIOS SIN IVA'!B25)/'2- EMP. REP'!B5 -> 79.466282 | C33: =+'5-PRECIOS SIN IVA'!C39*'2- EMP. REP'!C6*('5-PRECIOS SIN IVA'!C25)/'2- EMP. REP'!C5 -> 73.162937 | D33: =+'5-PRECIOS SIN IVA'!D39*'2- EMP. REP'!D6*('5-PRECIOS SIN IVA'!D25)/'2- EMP. REP'!D5 -> 55.455855 | E33: =+'5-PRECIOS SIN IVA'!E39*'2- EMP. REP'!E6*('5-PRECIOS SIN IVA'!E25)/'2- EMP. REP'!E5 -> 47.170158 | F33: =+'5-PRECIOS SIN IVA'!F39*'2- EMP. REP'!F6*('5-PRECIOS SIN IVA'!F25)/'2- EMP. REP'!F5 -> 48.6032 | G33: =+'5-PRECIOS SIN IVA'!G39*'2- EMP. REP'!G6*('5-PRECIOS SIN IVA'!G25)/'2- EMP. REP'!G5 -> 65.503764 | H33: =+'5-PRECIOS SIN IVA'!H39*'2- EMP. REP'!H6*('5-PRECIOS SIN IVA'!H25)/'2- EMP. REP'!H5 -> 48.097844 | I33: =+'5-PRECIOS SIN IVA'!I39*'2- EMP. REP'!I6*('5-PRECIOS SIN IVA'!I25)/'2- EMP. REP'!I5 -> 61.248134 | J33: =+'5-PRECIOS SIN IVA'!J39*'2- EMP. REP'!J6*('5-PRECIOS SIN IVA'!J25)/'2- EMP. REP'!J5 -> 56.905268 | L33: =+A33 -> . Chasis (incluye boletera y rampa) | V33: =+A33 -> . Chasis (incluye boletera y rampa) | AF33: =+L33 -> . Chasis (incluye boletera y rampa)
A34: . Carrocería | B34: =+'5-PRECIOS SIN IVA'!B39*'2- EMP. REP'!B6*'5-PRECIOS SIN IVA'!B26/'2- EMP. REP'!B5 -> 34.53744 | C34: =+'5-PRECIOS SIN IVA'!C39*'2- EMP. REP'!C6*'5-PRECIOS SIN IVA'!C26/'2- EMP. REP'!C5 -> 31.797896 | D34: =+'5-PRECIOS SIN IVA'!D39*'2- EMP. REP'!D6*'5-PRECIOS SIN IVA'!D26/'2- EMP. REP'!D5 -> 24.102087 | E34: =+'5-PRECIOS SIN IVA'!E39*'2- EMP. REP'!E6*'5-PRECIOS SIN IVA'!E26/'2- EMP. REP'!E5 -> 25.739352 | F34: =+'5-PRECIOS SIN IVA'!F39*'2- EMP. REP'!F6*'5-PRECIOS SIN IVA'!F26/'2- EMP. REP'!F5 -> 21.123803 | G34: =+'5-PRECIOS SIN IVA'!G39*'2- EMP. REP'!G6*'5-PRECIOS SIN IVA'!G26/'2- EMP. REP'!G5 -> 28.469085 | H34: =+'5-PRECIOS SIN IVA'!H39*'2- EMP. REP'!H6*'5-PRECIOS SIN IVA'!H26/'2- EMP. REP'!H5 -> 20.904167 | I34: =+'5-PRECIOS SIN IVA'!I39*'2- EMP. REP'!I6*'5-PRECIOS SIN IVA'!I26/'2- EMP. REP'!I5 -> 26.60574 | J34: =+'5-PRECIOS SIN IVA'!J39*'2- EMP. REP'!J6*'5-PRECIOS SIN IVA'!J26/'2- EMP. REP'!J5 -> 24.719231 | L34: =+A34 -> . Carrocería | V34: =+A34 -> . Carrocería | AF34: =+L34 -> . Carrocería
A35: . Máquinas y herramientas | B35: =+'5-PRECIOS SIN IVA'!B39*('5-PRECIOS SIN IVA'!B17+'5-PRECIOS SIN IVA'!B18)*(1+'3- REND Y CONS'!B48)/2*'2- EMP. REP'!B6*'3- REND Y CONS'!B45/'2- EMP. REP'!B5 -> 2.6057994 | C35: =+'5-PRECIOS SIN IVA'!C39*('5-PRECIOS SIN IVA'!C17+'5-PRECIOS SIN IVA'!C18)*(1+'3- REND Y CONS'!C48)/2*'2- EMP. REP'!C6*'3- REND Y CONS'!C45/'2- EMP. REP'!C5 -> 2.3991047 | D35: =+'5-PRECIOS SIN IVA'!D39*('5-PRECIOS SIN IVA'!D17+'5-PRECIOS SIN IVA'!D18)*(1+'3- REND Y CONS'!D48)/2*'2- EMP. REP'!D6*'3- REND Y CONS'!D45/'2- EMP. REP'!D5 -> 1.8184672 | E35: =+'5-PRECIOS SIN IVA'!E39*('5-PRECIOS SIN IVA'!E17+'5-PRECIOS SIN IVA'!E18)*(1+'3- REND Y CONS'!E48)/2*'2- EMP. REP'!E6*'3- REND Y CONS'!E45/'2- EMP. REP'!E5 -> 1.6665031 | F35: =+'5-PRECIOS SIN IVA'!F39*('5-PRECIOS SIN IVA'!F17+'5-PRECIOS SIN IVA'!F18)*(1+'3- REND Y CONS'!F48)/2*'2- EMP. REP'!F6*'3- REND Y CONS'!F45/'2- EMP. REP'!F5 -> 1.5937601 | G35: =+'5-PRECIOS SIN IVA'!G39*('5-PRECIOS SIN IVA'!G17+'5-PRECIOS SIN IVA'!G18)*(1+'3- REND Y CONS'!G48)/2*'2- EMP. REP'!G6*'3- REND Y CONS'!G45/'2- EMP. REP'!G5 -> 2.1479508 | H35: =+'5-PRECIOS SIN IVA'!H39*('5-PRECIOS SIN IVA'!H17+'5-PRECIOS SIN IVA'!H18)*(1+'3- REND Y CONS'!H48)/2*'2- EMP. REP'!H6*'3- REND Y CONS'!H45/'2- EMP. REP'!H5 -> 1.5771888 | I35: =+'5-PRECIOS SIN IVA'!I39*('5-PRECIOS SIN IVA'!I17+'5-PRECIOS SIN IVA'!I18)*(1+'3- REND Y CONS'!I48)/2*'2- EMP. REP'!I6*'3- REND Y CONS'!I45/'2- EMP. REP'!I5 -> 2.0080886 | J35: =+'5-PRECIOS SIN IVA'!J39*('5-PRECIOS SIN IVA'!J17+'5-PRECIOS SIN IVA'!J18)*(1+'3- REND Y CONS'!J48)/2*'2- EMP. REP'!J6*'3- REND Y CONS'!J45/'2- EMP. REP'!J5 -> 1.8657028 | L35: =+A35 -> . Máquinas y herramientas | V35: =+A35 -> . Máquinas y herramientas | AF35: =+L35 -> . Máquinas y herramientas
A36: . Inmuebles | B36: =+'5-PRECIOS SIN IVA'!B39*('3- REND Y CONS'!B34*'5-PRECIOS SIN IVA'!B44*(1+'3- REND Y CONS'!B43)/2+'3- REND Y CONS'!B35*'5-PRECIOS SIN IVA'!B45*(1+'3- REND Y CONS'!B43)/2+'3- REND Y CONS'!B33*'5-PRECIOS SIN IVA'!B43*(1+'3- REND Y CONS'!B44)/2+'3- REND Y CONS'!B36*'5-PRECIOS SIN IVA'!B46)/'2- EMP. REP'!B5 -> 22.404925 | C36: =+'5-PRECIOS SIN IVA'!C39*('3- REND Y CONS'!C34*'5-PRECIOS SIN IVA'!C44*(1+'3- REND Y CONS'!C43)/2+'3- REND Y CONS'!C35*'5-PRECIOS SIN IVA'!C45*(1+'3- REND Y CONS'!C43)/2+'3- REND Y CONS'!C33*'5-PRECIOS SIN IVA'!C43*(1+'3- REND Y CONS'!C44)/2+'3- REND Y CONS'!C36*'5-PRECIOS SIN IVA'!C46)/'2- EMP. REP'!C5 -> 20.627744 | D36: =+'5-PRECIOS SIN IVA'!D39*('3- REND Y CONS'!D34*'5-PRECIOS SIN IVA'!D44*(1+'3- REND Y CONS'!D43)/2+'3- REND Y CONS'!D35*'5-PRECIOS SIN IVA'!D45*(1+'3- REND Y CONS'!D43)/2+'3- REND Y CONS'!D33*'5-PRECIOS SIN IVA'!D43*(1+'3- REND Y CONS'!D44)/2+'3- REND Y CONS'!D36*'5-PRECIOS SIN IVA'!D46)/'2- EMP. REP'!D5 -> 15.635365 | E36: =+'5-PRECIOS SIN IVA'!E39*('3- REND Y CONS'!E34*'5-PRECIOS SIN IVA'!E44*(1+'3- REND Y CONS'!E43)/2+'3- REND Y CONS'!E35*'5-PRECIOS SIN IVA'!E45*(1+'3- REND Y CONS'!E43)/2+'3- REND Y CONS'!E33*'5-PRECIOS SIN IVA'!E43*(1+'3- REND Y CONS'!E44)/2+'3- REND Y CONS'!E36*'5-PRECIOS SIN IVA'!E46)/'2- EMP. REP'!E5 -> 11.20058 | F36: =+'5-PRECIOS SIN IVA'!F39*('3- REND Y CONS'!F34*'5-PRECIOS SIN IVA'!F44*(1+'3- REND Y CONS'!F43)/2+'3- REND Y CONS'!F35*'5-PRECIOS SIN IVA'!F45*(1+'3- REND Y CONS'!F43)/2+'3- REND Y CONS'!F33*'5-PRECIOS SIN IVA'!F43*(1+'3- REND Y CONS'!F44)/2+'3- REND Y CONS'!F36*'5-PRECIOS SIN IVA'!F46)/'2- EMP. REP'!F5 -> 10.207048 | G36: =+'5-PRECIOS SIN IVA'!G39*('3- REND Y CONS'!G34*'5-PRECIOS SIN IVA'!G44*(1+'3- REND Y CONS'!G43)/2+'3- REND Y CONS'!G35*'5-PRECIOS SIN IVA'!G45*(1+'3- REND Y CONS'!G43)/2+'3- REND Y CONS'!G33*'5-PRECIOS SIN IVA'!G43*(1+'3- REND Y CONS'!G44)/2+'3- REND Y CONS'!G36*'5-PRECIOS SIN IVA'!G46)/'2- EMP. REP'!G5 -> 13.756297 | H36: =+'5-PRECIOS SIN IVA'!H39*('3- REND Y CONS'!H34*'5-PRECIOS SIN IVA'!H44*(1+'3- REND Y CONS'!H43)/2+'3- REND Y CONS'!H35*'5-PRECIOS SIN IVA'!H45*(1+'3- REND Y CONS'!H43)/2+'3- REND Y CONS'!H33*'5-PRECIOS SIN IVA'!H43*(1+'3- REND Y CONS'!H44)/2+'3- REND Y CONS'!H36*'5-PRECIOS SIN IVA'!H46)/'2- EMP. REP'!H5 -> 10.100919 | I36: =+'5-PRECIOS SIN IVA'!I39*('3- REND Y CONS'!I34*'5-PRECIOS SIN IVA'!I44*(1+'3- REND Y CONS'!I43)/2+'3- REND Y CONS'!I35*'5-PRECIOS SIN IVA'!I45*(1+'3- REND Y CONS'!I43)/2+'3- REND Y CONS'!I33*'5-PRECIOS SIN IVA'!I43*(1+'3- REND Y CONS'!I44)/2+'3- REND Y CONS'!I36*'5-PRECIOS SIN IVA'!I46)/'2- EMP. REP'!I5 -> 14.859149 | J36: =+'5-PRECIOS SIN IVA'!J39*('3- REND Y CONS'!J34*'5-PRECIOS SIN IVA'!J44*(1+'3- REND Y CONS'!J43)/2+'3- REND Y CONS'!J35*'5-PRECIOS SIN IVA'!J45*(1+'3- REND Y CONS'!J43)/2+'3- REND Y CONS'!J33*'5-PRECIOS SIN IVA'!J43*(1+'3- REND Y CONS'!J44)/2+'3- REND Y CONS'!J36*'5-PRECIOS SIN IVA'!J46)/'2- EMP. REP'!J5 -> 13.805545 | L36: =+A36 -> . Inmuebles | V36: =+A36 -> . Inmuebles | AF36: =+L36 -> . Inmuebles
A37: 14. LICENCIA NACIONAL HABILITANTE | B37: =+'4- PERSONAL'!B135*'4- PERSONAL'!B136*'4- PERSONAL'!B26/'2- EMP. REP'!B5 -> 0.60584807 | C37: =+'4- PERSONAL'!C135*'4- PERSONAL'!C136*'4- PERSONAL'!C26/'2- EMP. REP'!C5 -> 0.57584032 | D37: =+'4- PERSONAL'!D135*'4- PERSONAL'!D136*'4- PERSONAL'!D26/'2- EMP. REP'!D5 -> 0.43647396 | E37: =+'4- PERSONAL'!E135*'4- PERSONAL'!E136*'4- PERSONAL'!E26/'2- EMP. REP'!E5 -> 0.29590831 | F37: =+'4- PERSONAL'!F135*'4- PERSONAL'!F136*'4- PERSONAL'!F26/'2- EMP. REP'!F5 -> 0.38253908 | G37: =+'4- PERSONAL'!G135*'4- PERSONAL'!G136*'4- PERSONAL'!G26/'2- EMP. REP'!G5 -> 0.5155576 | H37: =+'4- PERSONAL'!H135*'4- PERSONAL'!H136*'4- PERSONAL'!H26/'2- EMP. REP'!H5 -> 0.37856159 | I37: =+'4- PERSONAL'!I135*'4- PERSONAL'!I136*'4- PERSONAL'!I26/'2- EMP. REP'!I5 -> 0.53943545 | J37: =+'4- PERSONAL'!J135*'4- PERSONAL'!J136*'4- PERSONAL'!J26/'2- EMP. REP'!J5 -> 0.50118619 | L37: =+A37 -> 14. LICENCIA NACIONAL HABILITANTE | M37: =+B37/B$51 -> 0.0001563169 | N37: =+C37/C$51 -> 0.00016634745 | O37: =+D37/D$51 -> 0.0001565415 | P37: =+E37/E$51 -> 0.00012580054 | Q37: =+F37/F$51 -> 0.00016092683 | R37: =+G37/G$51 -> 0.00016751036 | S37: =+H37/H$51 -> 0.0001529482 | T37: =+I37/I$51 -> 0.0001735308 | U37: =+J37/J$51 -> 0.00017014559 | V37: =+A37 -> 14. LICENCIA NACIONAL HABILITANTE | W37: =+B37/'[1]1-COSTO X KM'!B37-1 -> -0.036502875 | X37: =+C37/'[1]1-COSTO X KM'!C37-1 -> 0.13691237 | Y37: =+D37/'[1]1-COSTO X KM'!D37-1 -> 0.14591101 | Z37: =+E37/'[1]1-COSTO X KM'!E37-1 -> 0.066687284 | AA37: =+F37/'[1]1-COSTO X KM'!F37-1 -> 0.2326877 | AB37: =+G37/'[1]1-COSTO X KM'!G37-1 -> 0.00014639259 | AC37: =+H37/'[1]1-COSTO X KM'!H37-1 -> 0.10480638 | AD37: =+I37/'[1]1-COSTO X KM'!I37-1 -> 0.016550488 | AE37: =+J37/'[1]1-COSTO X KM'!J37-1 -> 0.045033677 | AF37: =+L37 -> 14. LICENCIA NACIONAL HABILITANTE | AG37: =+B37/'[2]1-COSTO X KM'!B37-1 -> -0.04386068 | AH37: =+C37/'[2]1-COSTO X KM'!C37-1 -> -0.0060871408 | AI37: =+D37/'[2]1-COSTO X KM'!D37-1 -> 0.004508955 | AJ37: =+E37/'[2]1-COSTO X KM'!E37-1 -> -0.056579246 | AK37: =+F37/'[2]1-COSTO X KM'!F37-1 -> 0.098510161 | AL37: =+G37/'[2]1-COSTO X KM'!G37-1 -> 0.0011873132 | AM37: =+H37/'[2]1-COSTO X KM'!H37-1 -> 0.066887625 | AN37: =+I37/'[2]1-COSTO X KM'!I37-1 -> 0.016863276 | AO37: =+J37/'[2]1-COSTO X KM'!J37-1 -> 0.050321748
A38: 15. CONTROL TECNICO DEL MATERIAL RODANTE | B38: =+'3- REND Y CONS'!B28*'5-PRECIOS SIN IVA'!B23/'2- EMP. REP'!B8 -> 8.4174351 | C38: =+'3- REND Y CONS'!C28*'5-PRECIOS SIN IVA'!C23/'2- EMP. REP'!C8 -> 7.7497557 | D38: =+'3- REND Y CONS'!D28*'5-PRECIOS SIN IVA'!D23/'2- EMP. REP'!D8 -> 5.8741399 | E38: =+'3- REND Y CONS'!E28*'5-PRECIOS SIN IVA'!E23/'2- EMP. REP'!E8 -> 3.8719299 | F38: =+'3- REND Y CONS'!F28*'5-PRECIOS SIN IVA'!F23/'2- EMP. REP'!F8 -> 5.1482751 | G38: =+'3- REND Y CONS'!G28*'5-PRECIOS SIN IVA'!G23/'2- EMP. REP'!G8 -> 6.9384608 | H38: =+'3- REND Y CONS'!H28*'5-PRECIOS SIN IVA'!H23/'2- EMP. REP'!H8 -> 5.0947455 | I38: =+'3- REND Y CONS'!I28*'5-PRECIOS SIN IVA'!I23/'2- EMP. REP'!I8 -> 7.494722 | J38: =+'3- REND Y CONS'!J28*'5-PRECIOS SIN IVA'!J23/'2- EMP. REP'!J8 -> 6.9633006 | L38: =+A38 -> 15. CONTROL TECNICO DEL MATERIAL RODANTE | M38: =+B38/B$51 -> 0.0021718107 | N38: =+C38/C$51 -> 0.0022387319 | O38: =+D38/D$51 -> 0.0021067618 | P38: =+E38/E$51 -> 0.0016460871 | Q38: =+F38/F$51 -> 0.0021657803 | R38: =+G38/G$51 -> 0.0022543825 | S38: =+H38/H$51 -> 0.0020584026 | T38: =+I38/I$51 -> 0.0024109745 | U38: =+J38/J$51 -> 0.0023639416 | V38: =+A38 -> 15. CONTROL TECNICO DEL MATERIAL RODANTE | W38: =+B38/'[1]1-COSTO X KM'!B38-1 -> 0.20194567 | X38: =+C38/'[1]1-COSTO X KM'!C38-1 -> 0.41821782 | Y38: =+D38/'[1]1-COSTO X KM'!D38-1 -> 0.429443 | Z38: =+E38/'[1]1-COSTO X KM'!E38-1 -> 0.33061694 | AA38: =+F38/'[1]1-COSTO X KM'!F38-1 -> 0.53769079 | AB38: =+G38/'[1]1-COSTO X KM'!G38-1 -> 0.24761194 | AC38: =+H38/'[1]1-COSTO X KM'!H38-1 -> 0.37816788 | AD38: =+I38/'[1]1-COSTO X KM'!I38-1 -> 0.2681288 | AE38: =+J38/'[1]1-COSTO X KM'!J38-1 -> 0.30366108 | AF38: =+L38 -> 15. CONTROL TECNICO DEL MATERIAL RODANTE | AG38: =+B38/'[2]1-COSTO X KM'!B38-1 -> 0.14763684 | AH38: =+C38/'[2]1-COSTO X KM'!C38-1 -> 0.19292491 | AI38: =+D38/'[2]1-COSTO X KM'!D38-1 -> 0.20564267 | AJ38: =+E38/'[2]1-COSTO X KM'!E38-1 -> 0.13232273 | AK38: =+F38/'[2]1-COSTO X KM'!F38-1 -> 0.31846582 | AL38: =+G38/'[2]1-COSTO X KM'!G38-1 -> 0.20165594 | AM38: =+H38/'[2]1-COSTO X KM'!H38-1 -> 0.28051148 | AN38: =+I38/'[2]1-COSTO X KM'!I38-1 -> 0.22052271 | AO38: =+J38/'[2]1-COSTO X KM'!J38-1 -> 0.26068231
A39: 16. A.C.TRANS | B39: =+'2- EMP. REP'!B6*'5-PRECIOS SIN IVA'!B38/('2- EMP. REP'!B5/12) -> 0.0076485773 | C39: =+'2- EMP. REP'!C6*'5-PRECIOS SIN IVA'!C38/('2- EMP. REP'!C5/12) -> 0.0070418845 | D39: =+'2- EMP. REP'!D6*'5-PRECIOS SIN IVA'!D38/('2- EMP. REP'!D5/12) -> 0.0053375895 | E39: =+'2- EMP. REP'!E6*'5-PRECIOS SIN IVA'!E38/('2- EMP. REP'!E5/12) -> 0.0035182635 | F39: =+'2- EMP. REP'!F6*'5-PRECIOS SIN IVA'!F38/('2- EMP. REP'!F5/12) -> 0.004678026 | G39: =+'2- EMP. REP'!G6*'5-PRECIOS SIN IVA'!G38/('2- EMP. REP'!G5/12) -> 0.0063046942 | H39: =+'2- EMP. REP'!H6*'5-PRECIOS SIN IVA'!H38/('2- EMP. REP'!H5/12) -> 0.0046293858 | I39: =+'2- EMP. REP'!I6*'5-PRECIOS SIN IVA'!I38/('2- EMP. REP'!I5/12) -> 0.0068101459 | J39: =+'2- EMP. REP'!J6*'5-PRECIOS SIN IVA'!J38/('2- EMP. REP'!J5/12) -> 0.0063272651 | L39: =+A39 -> 16. A.C.TRANS | M39: =+B39/B$51 -> 1.9734352e-06 | N39: =+C39/C$51 -> 2.0342437e-06 | O39: =+D39/D$51 -> 1.9143279e-06 | P39: =+E39/E$51 -> 1.4957317e-06 | Q39: =+F39/F$51 -> 1.9679555e-06 | R39: =+G39/G$51 -> 2.0484648e-06 | S39: =+H39/H$51 -> 1.8703858e-06 | T39: =+I39/I$51 -> 2.1907534e-06 | U39: =+J39/J$51 -> 2.1480166e-06 | V39: =+A39 -> 16. A.C.TRANS | W39: =+B39/'[1]1-COSTO X KM'!B39-1 -> -0.036461882 | X39: =+C39/'[1]1-COSTO X KM'!C39-1 -> 0.1369124 | Y39: =+D39/'[1]1-COSTO X KM'!D39-1 -> 0.14591105 | Z39: =+E39/'[1]1-COSTO X KM'!E39-1 -> 0.066687269 | AA39: =+F39/'[1]1-COSTO X KM'!F39-1 -> 0.23268774 | AB39: =+G39/'[1]1-COSTO X KM'!G39-1 -> 0.00014642168 | AC39: =+H39/'[1]1-COSTO X KM'!H39-1 -> 0.10480641 | AD39: =+I39/'[1]1-COSTO X KM'!I39-1 -> 0.016593738 | AE39: =+J39/'[1]1-COSTO X KM'!J39-1 -> 0.04507814 | AF39: =+L39 -> 16. A.C.TRANS | AG39: =+B39/'[2]1-COSTO X KM'!B39-1 -> -0.043819942 | AH39: =+C39/'[2]1-COSTO X KM'!C39-1 -> -0.0060871408 | AI39: =+D39/'[2]1-COSTO X KM'!D39-1 -> 0.004508955 | AJ39: =+E39/'[2]1-COSTO X KM'!E39-1 -> -0.056579246 | AK39: =+F39/'[2]1-COSTO X KM'!F39-1 -> 0.098510161 | AL39: =+G39/'[2]1-COSTO X KM'!G39-1 -> 0.0011873132 | AM39: =+H39/'[2]1-COSTO X KM'!H39-1 -> 0.066887625 | AN39: =+I39/'[2]1-COSTO X KM'!I39-1 -> 0.016906601 | AO39: =+J39/'[2]1-COSTO X KM'!J39-1 -> 0.050366499
A40: 17. PEAJES | B40: 0 | C40: 0 | D40: 0 | E40: 0.173 | F40: 0.014 | G40: 0 | H40: 0 | I40: 0 | J40: 0 | L40: =+A40 -> 17. PEAJES | M40: =+B40/B$51 -> 0 | N40: =+C40/C$51 -> 0 | O40: =+D40/D$51 -> 0 | P40: =+E40/E$51 -> 7.3548096e-05 | Q40: =+F40/F$51 -> 5.8895306e-06 | R40: =+G40/G$51 -> 0 | S40: =+H40/H$51 -> 0 | T40: =+I40/I$51 -> 0 | U40: =+J40/J$51 -> 0 | V40: =+A40 -> 17. PEAJES | Z40: =+E40/'[1]1-COSTO X KM'!E40-1 -> 0 | AA40: =+F40/'[1]1-COSTO X KM'!F40-1 -> 0 | AF40: =+L40 -> 17. PEAJES | AG40: =+B40/'[2]1-COSTO X KM'!B40-1 -> #DIV/0! | AH40: =+C40/'[2]1-COSTO X KM'!C40-1 -> #DIV/0! | AI40: =+D40/'[2]1-COSTO X KM'!D40-1 -> #DIV/0! | AJ40: =+E40/'[2]1-COSTO X KM'!E40-1 -> 0 | AK40: =+F40/'[2]1-COSTO X KM'!F40-1 -> 0 | AL40: =+G40/'[2]1-COSTO X KM'!G40-1 -> #DIV/0! | AM40: =+H40/'[2]1-COSTO X KM'!H40-1 -> #DIV/0! | AN40: =+I40/'[2]1-COSTO X KM'!I40-1 -> #DIV/0! | AO40: =+J40/'[2]1-COSTO X KM'!J40-1 -> #DIV/0!
...

Sheet 2- EMP. REP
A1: ANEXO 2- CARACTERÍSTICAS DE LAS EMPRESAS REPRESENTATIVAS
A3: CARACTERÍSTICAS DE LA EMPRESA | B3: DF | C3: SGI | D3: SGI KM | E3: SGII | F3: INP | G3: UPA | H3: UPA KM | I3: UMA 1 | J3: UMA 2
A4: PASAJEROS TRANSPORTADOS | B4: =+'7-CALCULO TARIFARIO'!B11/'7-CALCULO TARIFARIO'!B6 -> 9679415 | C4: =+'7-CALCULO TARIFARIO'!C11/'7-CALCULO TARIFARIO'!C6 -> 10306100 | D4: =+'7-CALCULO TARIFARIO'!D11/'7-CALCULO TARIFARIO'!D6 -> 23348447 | E4: =+'7-CALCULO TARIFARIO'!E11/'7-CALCULO TARIFARIO'!E6 -> 9125216.8 | F4: =+'7-CALCULO TARIFARIO'!F11/'7-CALCULO TARIFARIO'!F6 -> 1716370.4 | G4: =+'7-CALCULO TARIFARIO'!G11/'7-CALCULO TARIFARIO'!G6 -> 6993861.5 | H4: =+'7-CALCULO TARIFARIO'!H11/'7-CALCULO TARIFARIO'!H6 -> 6906949.7 | I4: =+'7-CALCULO TARIFARIO'!I11/'7-CALCULO TARIFARIO'!I6 -> 6120900.7 | J4: =+'7-CALCULO TARIFARIO'!J11/'7-CALCULO TARIFARIO'!J6 -> 3193089.4
